Workbook

Sheet Калькулятор инвестора
B1: КАЛЬКУЛЯТОР ИНВЕСТОРА — КАФЕ «ВЕНСКИЙ ВЕТЕР» https://cafe-spb.ru/
B2: 🟡 Жёлтые ячейки — меняйте сами. Сценарий переключается на листе «Вводные» (ячейка C5: 1=Оптим., 2=Реалист., 3=Пессим.)
B4: ПАРАМЕТРЫ СДЕЛКИ
B5: Ваша сумма инвестиции, руб. | C5: 1000000 | D5: Введите вашу сумму
B6: Доля прибыли инвестора ДО возврата, % | C6: 0.7 | D6: Доля прибыли до полного возврата вложений (70%)
B7: Доля прибыли инвестора ПОСЛЕ возврата, % | C7: 0.3 | D7: Доля прибыли после окупаемости (30%)
B8: Текущий сценарий | C8: =IF('Вводные'!C5=1,"Оптимистичный",IF('Вводные'!C5=2,"Реалистичный","Пессимистичный")) -> Реалистичный | D8: Переключается на листе «Вводные» → ячейка C5
B10: ПАРАМЕТРЫ ПРОЕКТА (из модели)
B11: Общий инвест. бюджет проекта, руб. | C11: ='Вводные'!F48 -> 4642311 | D11: Меняется при смене сценария
B12: Доля инвестора в объёме инвестиций, % | C12: =C5/C11 -> 0.21540995
B13: Прогнозируемое распределение прибыли | C13: "70%→30% Инвестор" | D13: Устанавливается в ячейке C6 выше; используется в расчётах ниже
B15: ФИНАНСОВЫЕ ПОКАЗАТЕЛИ ЗА 36 МЕС. (из финмодели)
B16: Выручка итого за 36 мес., руб. | C16: ='Фин.модель'!AP4 -> 119700000
B17: Чистая прибыль итого за 36 мес., руб. | C17: ='Фин.модель'!AP34 -> 42120312
B18: Средняя ежемесячная прибыль, руб. | C18: =C17/36 -> 1170008.7
B19: Средняя рентабельность за 36 мес. | C19: =IFERROR(C17/C16,0) -> 0.35188231
B21: ПРОГНОЗ ВЫПЛАТ ИНВЕСТОРУ (36 МЕСЯЦЕВ)
B22: Месяц | C22: Прибыль проекта, руб. | D22: Выплата инвестору, руб. | E22: Нарастающий итог выплат, руб. | F22: Возврат инвестиции, руб. | G22: Статус (до/после возврата)
B23: 1 | C23: ='Фин.модель'!C34 -> 206642 | D23: =IF(C23<=0,0,IF(0>=$C$5,MAX(C23*$C$12*$C$7,0),MAX(C23*$C$12*$C$6,0))) -> 31158.921 | E23: =D23 -> 31158.921 | F23: =MAX($C$5-E23,0) -> 968841.08 | G23: =IF(0>=$C$5,"✅ 30% (возврат завершён)","⏳ 70% (идёт возврат)") -> ⏳ 70% (идёт возврат)
B24: 2 | C24: ='Фин.модель'!D34 -> 316482 | D24: =IF(C24<=0,0,IF(E23>=$C$5,MAX(C24*$C$12*$C$7,0),MAX(C24*$C$12*$C$6,0))) -> 47721.361 | E24: =E23+D24 -> 78880.282 | F24: =MAX($C$5-E24,0) -> 921119.72 | G24: =IF(E23>=$C$5,"✅ 30% (возврат завершён)","⏳ 70% (идёт возврат)") -> ⏳ 70% (идёт возврат)
B25: 3 | C25: ='Фин.модель'!E34 -> 426322 | D25: =IF(C25<=0,0,IF(E24>=$C$5,MAX(C25*$C$12*$C$7,0),MAX(C25*$C$12*$C$6,0))) -> 64283.802 | E25: =E24+D25 -> 143164.08 | F25: =MAX($C$5-E25,0) -> 856835.92 | G25: =IF(E24>=$C$5,"✅ 30% (возврат завершён)","⏳ 70% (идёт возврат)") -> ⏳ 70% (идёт возврат)
B26: 4 | C26: ='Фин.модель'!F34 -> 541162 | D26: =IF(C26<=0,0,IF(E25>=$C$5,MAX(C26*$C$12*$C$7,0),MAX(C26*$C$12*$C$6,0))) -> 81600.177 | E26: =E25+D26 -> 224764.26 | F26: =MAX($C$5-E26,0) -> 775235.74 | G26: =IF(E25>=$C$5,"✅ 30% (возврат завершён)","⏳ 70% (идёт возврат)") -> ⏳ 70% (идёт возврат)
B27: 5 | C27: ='Фин.модель'!G34 -> 656002 | D27: =IF(C27<=0,0,IF(E26>=$C$5,MAX(C27*$C$12*$C$7,0),MAX(C27*$C$12*$C$6,0))) -> 98916.553 | E27: =E26+D27 -> 323680.81 | F27: =MAX($C$5-E27,0) -> 676319.19 | G27: =IF(E26>=$C$5,"✅ 30% (возврат завершён)","⏳ 70% (идёт возврат)") -> ⏳ 70% (идёт возврат)
B28: 6 | C28: ='Фин.модель'!H34 -> 770842 | D28: =IF(C28<=0,0,IF(E27>=$C$5,MAX(C28*$C$12*$C$7,0),MAX(C28*$C$12*$C$6,0))) -> 116232.93 | E28: =E27+D28 -> 439913.74 | F28: =MAX($C$5-E28,0) -> 560086.26 | G28: =IF(E27>=$C$5,"✅ 30% (возврат завершён)","⏳ 70% (идёт возврат)") -> ⏳ 70% (идёт возврат)
B29: 7 | C29: ='Фин.модель'!I34 -> 885682 | D29: =IF(C29<=0,0,IF(E28>=$C$5,MAX(C29*$C$12*$C$7,0),MAX(C29*$C$12*$C$6,0))) -> 133549.3 | E29: =E28+D29 -> 573463.04 | F29: =MAX($C$5-E29,0) -> 426536.96 | G29: =IF(E28>=$C$5,"✅ 30% (возврат завершён)","⏳ 70% (идёт возврат)") -> ⏳ 70% (идёт возврат)
B30: 8 | C30: ='Фин.модель'!J34 -> 1000522 | D30: =IF(C30<=0,0,IF(E29>=$C$5,MAX(C30*$C$12*$C$7,0),MAX(C30*$C$12*$C$6,0))) -> 150865.68 | E30: =E29+D30 -> 724328.72 | F30: =MAX($C$5-E30,0) -> 275671.28 | G30: =IF(E29>=$C$5,"✅ 30% (возврат завершён)","⏳ 70% (идёт возврат)") -> ⏳ 70% (идёт возврат)
B31: 9 | C31: ='Фин.модель'!K34 -> 1115362 | D31: =IF(C31<=0,0,IF(E30>=$C$5,MAX(C31*$C$12*$C$7,0),MAX(C31*$C$12*$C$6,0))) -> 168182.05 | E31: =E30+D31 -> 892510.78 | F31: =MAX($C$5-E31,0) -> 107489.22 | G31: =IF(E30>=$C$5,"✅ 30% (возврат завершён)","⏳ 70% (идёт возврат)") -> ⏳ 70% (идёт возврат)
B32: 10 | C32: ='Фин.модель'!L34 -> 1230202 | D32: =IF(C32<=0,0,IF(E31>=$C$5,MAX(C32*$C$12*$C$7,0),MAX(C32*$C$12*$C$6,0))) -> 185498.43 | E32: =E31+D32 -> 1078009.2 | F32: =MAX($C$5-E32,0) -> 0 | G32: =IF(E31>=$C$5,"✅ 30% (возврат завершён)","⏳ 70% (идёт возврат)") -> ⏳ 70% (идёт возврат)
B33: 11 | C33: ='Фин.модель'!M34 -> 1345042 | D33: =IF(C33<=0,0,IF(E32>=$C$5,MAX(C33*$C$12*$C$7,0),MAX(C33*$C$12*$C$6,0))) -> 86920.631 | E33: =E32+D33 -> 1164929.8 | F33: =MAX($C$5-E33,0) -> 0 | G33: =IF(E32>=$C$5,"✅ 30% (возврат завершён)","⏳ 70% (идёт возврат)") -> ✅ 30% (возврат завершён)
B34: 12 | C34: ='Фин.модель'!N34 -> 1345042 | D34: =IF(C34<=0,0,IF(E33>=$C$5,MAX(C34*$C$12*$C$7,0),MAX(C34*$C$12*$C$6,0))) -> 86920.631 | E34: =E33+D34 -> 1251850.5 | F34: =MAX($C$5-E34,0) -> 0 | G34: =IF(E33>=$C$5,"✅ 30% (возврат завершён)","⏳ 70% (идёт возврат)") -> ✅ 30% (возврат завершён)
B35: 13 | C35: ='Фин.модель'!O34 -> 1345042 | D35: =IF(C35<=0,0,IF(E34>=$C$5,MAX(C35*$C$12*$C$7,0),MAX(C35*$C$12*$C$6,0))) -> 86920.631 | E35: =E34+D35 -> 1338771.1 | F35: =MAX($C$5-E35,0) -> 0 | G35: =IF(E34>=$C$5,"✅ 30% (возврат завершён)","⏳ 70% (идёт возврат)") -> ✅ 30% (возврат завершён)
B36: 14 | C36: ='Фин.модель'!P34 -> 1345042 | D36: =IF(C36<=0,0,IF(E35>=$C$5,MAX(C36*$C$12*$C$7,0),MAX(C36*$C$12*$C$6,0))) -> 86920.631 | E36: =E35+D36 -> 1425691.7 | F36: =MAX($C$5-E36,0) -> 0 | G36: =IF(E35>=$C$5,"✅ 30% (возврат завершён)","⏳ 70% (идёт возврат)") -> ✅ 30% (возврат завершён)
B37: 15 | C37: ='Фин.модель'!Q34 -> 1345042 | D37: =IF(C37<=0,0,IF(E36>=$C$5,MAX(C37*$C$12*$C$7,0),MAX(C37*$C$12*$C$6,0))) -> 86920.631 | E37: =E36+D37 -> 1512612.4 | F37: =MAX($C$5-E37,0) -> 0 | G37: =IF(E36>=$C$5,"✅ 30% (возврат завершён)","⏳ 70% (идёт возврат)") -> ✅ 30% (возврат завершён)
B38: 16 | C38: ='Фин.модель'!R34 -> 1345042 | D38: =IF(C38<=0,0,IF(E37>=$C$5,MAX(C38*$C$12*$C$7,0),MAX(C38*$C$12*$C$6,0))) -> 86920.631 | E38: =E37+D38 -> 1599533 | F38: =MAX($C$5-E38,0) -> 0 | G38: =IF(E37>=$C$5,"✅ 30% (возврат завершён)","⏳ 70% (идёт возврат)") -> ✅ 30% (возврат завершён)
B39: 17 | C39: ='Фин.модель'!S34 -> 1345042 | D39: =IF(C39<=0,0,IF(E38>=$C$5,MAX(C39*$C$12*$C$7,0),MAX(C39*$C$12*$C$6,0))) -> 86920.631 | E39: =E38+D39 -> 1686453.6 | F39: =MAX($C$5-E39,0) -> 0 | G39: =IF(E38>=$C$5,"✅ 30% (возврат завершён)","⏳ 70% (идёт возврат)") -> ✅ 30% (возврат завершён)
B40: 18 | C40: ='Фин.модель'!T34 -> 1345042 | D40: =IF(C40<=0,0,IF(E39>=$C$5,MAX(C40*$C$12*$C$7,0),MAX(C40*$C$12*$C$6,0))) -> 86920.631 | E40: =E39+D40 -> 1773374.3 | F40: =MAX($C$5-E40,0) -> 0 | G40: =IF(E39>=$C$5,"✅ 30% (возврат завершён)","⏳ 70% (идёт возврат)") -> ✅ 30% (возврат завершён)
B41: 19 | C41: ='Фин.модель'!U34 -> 1345042 | D41: =IF(C41<=0,0,IF(E40>=$C$5,MAX(C41*$C$12*$C$7,0),MAX(C41*$C$12*$C$6,0))) -> 86920.631 | E41: =E40+D41 -> 1860294.9 | F41: =MAX($C$5-E41,0) -> 0 | G41: =IF(E40>=$C$5,"✅ 30% (возврат завершён)","⏳ 70% (идёт возврат)") -> ✅ 30% (возврат завершён)
B42: 20 | C42: ='Фин.модель'!V34 -> 1345042 | D42: =IF(C42<=0,0,IF(E41>=$C$5,MAX(C42*$C$12*$C$7,0),MAX(C42*$C$12*$C$6,0))) -> 86920.631 | E42: =E41+D42 -> 1947215.5 | F42: =MAX($C$5-E42,0) -> 0 | G42: =IF(E41>=$C$5,"✅ 30% (возврат завершён)","⏳ 70% (идёт возврат)") -> ✅ 30% (возврат завершён)
B43: 21 | C43: ='Фин.модель'!W34 -> 1345042 | D43: =IF(C43<=0,0,IF(E42>=$C$5,MAX(C43*$C$12*$C$7,0),MAX(C43*$C$12*$C$6,0))) -> 86920.631 | E43: =E42+D43 -> 2034136.1 | F43: =MAX($C$5-E43,0) -> 0 | G43: =IF(E42>=$C$5,"✅ 30% (возврат завершён)","⏳ 70% (идёт возврат)") -> ✅ 30% (возврат завершён)
B44: 22 | C44: ='Фин.модель'!X34 -> 1345042 | D44: =IF(C44<=0,0,IF(E43>=$C$5,MAX(C44*$C$12*$C$7,0),MAX(C44*$C$12*$C$6,0))) -> 86920.631 | E44: =E43+D44 -> 2121056.8 | F44: =MAX($C$5-E44,0) -> 0 | G44: =IF(E43>=$C$5,"✅ 30% (возврат завершён)","⏳ 70% (идёт возврат)") -> ✅ 30% (возврат завершён)
...

Sheet Вводные
B1: ВВОДНЫЕ ДАННЫЕ — Финансовая модель кафе (3 сценария, 36 месяцев)
B3: ▶ ВЫБОР СЦЕНАРИЯ
B4: Введите 1 = Оптимистичный | 2 = Реалистичный | 3 = Пессимистичный
B5: Сценарий (1 / 2 / 3): | C5: 2 | D5: ← измените это число | F5: =IF(C5=1,"✅ Оптимистичный",IF(C5=2,"✅ Реалистичный","✅ Пессимистичный")) -> ✅ Реалистичный
B7: Показатель | C7: Оптимистичный | D7: Реалистичный | E7: Пессимистичный | F7: Текущий сценарий →
B8: 1. КЛИЕНТСКИЙ ПОТОК
B9: Средний чек, руб. | C9: 750 | D9: 600 | E9: 500 | F9: =CHOOSE($C$5,C9,D9,E9) -> 600
B10: Начальное кол-во чеков/день (мес.1) | C10: 200 | D10: 100 | E10: 60 | F10: =CHOOSE($C$5,C10,D10,E10) -> 100
B11: Прирост чеков/день в мес. (ежемес.) | C11: 10 | D11: 10 | E11: 10 | F11: =CHOOSE($C$5,C11,D11,E11) -> 10
B12: Плато чеков/день (максимум) | C12: 300 | D12: 200 | E12: 150 | F12: =CHOOSE($C$5,C12,D12,E12) -> 200
B13: Рабочих дней в месяц | C13: 30 | D13: 30 | E13: 30 | F13: =CHOOSE($C$5,C13,D13,E13) -> 30
B15: 2. ПЕРЕМЕННЫЕ РАСХОДЫ (% от выручки)
B16: Себестоимость продуктов (COGS), % | C16: 0.3 | D16: 0.3 | E16: 0.3 | F16: =CHOOSE($C$5,C16,D16,E16) -> 0.3
B17: Эквайринг (80% платежей картой), % | C17: 0.015 | D17: 0.015 | E17: 0.015 | F17: =CHOOSE($C$5,C17,D17,E17) -> 0.015
B18: Маркетинг, % | C18: 0.02 | D18: 0.05 | E18: 0.1 | F18: =CHOOSE($C$5,C18,D18,E18) -> 0.05
B20: 3. ПЕРЕМЕННЫЙ ФОТ — ТЕХНИК + ПРЕМИИ (руб./мес.)
B21: Структура: ФОТ перем. = Техник (фикс.) + Премии (нарастающие с мес.2)
B22: Техник (аутсорс, фиксированно), руб. | C22: 5000 | D22: 5000 | E22: 5000 | F22: =CHOOSE($C$5,C22,D22,E22) -> 5000
B23: Прирост премий с мес.2, руб./мес. | C23: 5000 | D23: 5000 | E23: 5000 | F23: =CHOOSE($C$5,C23,D23,E23) -> 5000
B24: Максимум премий, руб. | C24: 10000 | D24: 10000 | E24: 10000 | F24: =CHOOSE($C$5,C24,D24,E24) -> 10000
B25: Расходные материалы (фикс.), руб. | C25: 20000 | D25: 20000 | E25: 20000 | F25: =CHOOSE($C$5,C25,D25,E25) -> 20000
B27: 4. ПОСТОЯННЫЕ РАСХОДЫ (руб./мес.)
B28: Аренда | C28: 220000 | D28: 220000 | E28: 220000 | F28: =CHOOSE($C$5,C28,D28,E28) -> 220000
B29: Коммуналка | C29: 50000 | D29: 50000 | E29: 50000 | F29: =CHOOSE($C$5,C29,D29,E29) -> 50000
B30: П.О. (программное обеспечение) | C30: 6658 | D30: 6658 | E30: 6658 | F30: =CHOOSE($C$5,C30,D30,E30) -> 6658
B31: Охранная система | C31: 3500 | D31: 3500 | E31: 3500 | F31: =CHOOSE($C$5,C31,D31,E31) -> 3500
B32: Связь / интернет | C32: 2000 | D32: 2000 | E32: 2000 | F32: =CHOOSE($C$5,C32,D32,E32) -> 2000
B33: ФОТ постоянный — итого | C33: 440000 | D33: 440000 | E33: 440000 | F33: =CHOOSE($C$5,C33,D33,E33) -> 440000
B34: Бариста-кассира (2 × 80 000) | C34: 160000 | D34: 160000 | E34: 160000 | F34: =CHOOSE($C$5,C34,D34,E34) -> 160000
B35: Повар (2 × 120 000) | C35: 240000 | D35: 240000 | E35: 240000 | F35: =CHOOSE($C$5,C35,D35,E35) -> 240000
B36: Менеджер | C36: 40000 | D36: 40000 | E36: 40000 | F36: =CHOOSE($C$5,C36,D36,E36) -> 40000
B37: Налоги и платежи за сотрудников | C37: 149600 | D37: 149600 | E37: 149600 | F37: =CHOOSE($C$5,C37,D37,E37) -> 149600
B38: Уборщица аутсорс | C38: 0 | D38: 0 | E38: 0 | F38: =CHOOSE($C$5,C38,D38,E38) -> 0
B39: Бухгалтер | C39: 20000 | D39: 20000 | E39: 20000 | F39: =CHOOSE($C$5,C39,D39,E39) -> 20000
B41: 5. НАЛОГИ (руб./мес., фиксированные)
B42: Налоги (УСН/патент), руб./мес. | C42: 25000 | D42: 25000 | E42: 25000 | F42: =CHOOSE($C$5,C42,D42,E42) -> 25000
B44: 6. ИНВЕСТИЦИОННЫЙ БЮДЖЕТ
B45: Единственное отличие между сценариями — продукты на 1-й мес (35% от планируемой выручки)
B46: Продукты на 1-й мес. (35% выручки М1), руб. | C46: 1037400 | D46: 518700 | E46: 259350 | F46: =CHOOSE($C$5,C46,D46,E46) -> 518700
B47: Прочие статьи бюджета (фикс. для всех), руб. | C47: 4123611 | D47: 4123611 | E47: 4123611 | F47: =CHOOSE($C$5,C47,D47,E47) -> 4123611
...

Sheet Фин.модель
B1: =IF('Вводные'!C5=1,"ФИНАНСОВАЯ МОДЕЛЬ — ОПТИМИСТИЧНЫЙ СЦЕНАРИЙ",IF('Вводные'!C5=2,"ФИНАНСОВАЯ МОДЕЛЬ — РЕАЛИСТИЧНЫЙ СЦЕНАРИЙ","ФИНАНСОВАЯ МОДЕЛЬ — ПЕССИМИСТИЧНЫЙ СЦЕНАРИЙ")) -> ФИНАНСОВАЯ МОДЕЛЬ — РЕАЛИСТИЧНЫЙ СЦЕНАРИЙ
B2: Мес.№ | C2: 1 | D2: 2 | E2: 3 | F2: 4 | G2: 5 | H2: 6 | I2: 7 | J2: 8 | K2: 9 | L2: 10 | M2: 11 | N2: 12 | O2: 13 | P2: 14 | Q2: 15 | R2: 16 | S2: 17 | T2: 18 | U2: 19 | V2: 20 | W2: 21 | X2: 22 | Y2: 23 | Z2: 24 | AA2: 25 | AB2: 26 | AC2: 27 | AD2: 28 | AE2: 29 | AF2: 30 | AG2: 31 | AH2: 32 | AI2: 33 | AJ2: 34 | AK2: 35 | AL2: 36 | AM2: ГОД 1 | AN2: ГОД 2 | AO2: ГОД 3 | AP2: ИТОГО
B3: Статья | C3: Мес.1 | D3: Мес.2 | E3: Мес.3 | F3: Мес.4 | G3: Мес.5 | H3: Мес.6 | I3: Мес.7 | J3: Мес.8 | K3: Мес.9 | L3: Мес.10 | M3: Мес.11 | N3: Мес.12 | O3: Мес.13 | P3: Мес.14 | Q3: Мес.15 | R3: Мес.16 | S3: Мес.17 | T3: Мес.18 | U3: Мес.19 | V3: Мес.20 | W3: Мес.21 | X3: Мес.22 | Y3: Мес.23 | Z3: Мес.24 | AA3: Мес.25 | AB3: Мес.26 | AC3: Мес.27 | AD3: Мес.28 | AE3: Мес.29 | AF3: Мес.30 | AG3: Мес.31 | AH3: Мес.32 | AI3: Мес.33 | AJ3: Мес.34 | AK3: Мес.35 | AL3: Мес.36 | AM3: ГОД 1 | AN3: ГОД 2 | AO3: ГОД 3 | AP3: ИТОГО 36 МЕС.
B4: ДОХОДЫ | C4: =C6*C5 -> 1800000 | D4: =D6*D5 -> 1980000 | E4: =E6*E5 -> 2160000 | F4: =F6*F5 -> 2340000 | G4: =G6*G5 -> 2520000 | H4: =H6*H5 -> 2700000 | I4: =I6*I5 -> 2880000 | J4: =J6*J5 -> 3060000 | ... AL4: =AL6*AL5 -> 3600000 | AM4: =SUM(C4:N4) -> 33300000 | AN4: =SUM(O4:Z4) -> 43200000 | AO4: =SUM(AA4:AL4) -> 43200000 | AP4: =SUM(AM4:AO4) -> 119700000
B5: Средний чек, руб. | C5: ='Вводные'!$F$9 -> 600 | D5: ='Вводные'!$F$9 -> 600 | E5: ='Вводные'!$F$9 -> 600 | F5: ='Вводные'!$F$9 -> 600 | G5: ='Вводные'!$F$9 -> 600 | H5: ='Вводные'!$F$9 -> 600 | I5: ='Вводные'!$F$9 -> 600 | J5: ='Вводные'!$F$9 -> 600 | ... AL5: ='Вводные'!$F$9 -> 600 | AM5: =SUM(C5:N5) -> 7200 | AN5: =SUM(O5:Z5) -> 7200 | AO5: =SUM(AA5:AL5) -> 7200 | AP5: =SUM(AM5:AO5) -> 21600
B6: Кол-во чеков/мес. | C6: =MIN('Вводные'!$F$10+(C$2-1)*'Вводные'!$F$11,'Вводные'!$F$12)*'Вводные'!$F$13 -> 3000 | D6: =MIN('Вводные'!$F$10+(D$2-1)*'Вводные'!$F$11,'Вводные'!$F$12)*'Вводные'!$F$13 -> 3300 | E6: =MIN('Вводные'!$F$10+(E$2-1)*'Вводные'!$F$11,'Вводные'!$F$12)*'Вводные'!$F$13 -> 3600 | F6: =MIN('Вводные'!$F$10+(F$2-1)*'Вводные'!$F$11,'Вводные'!$F$12)*'Вводные'!$F$13 -> 3900 | G6: =MIN('Вводные'!$F$10+(G$2-1)*'Вводные'!$F$11,'Вводные'!$F$12)*'Вводные'!$F$13 -> 4200 | H6: =MIN('Вводные'!$F$10+(H$2-1)*'Вводные'!$F$11,'Вводные'!$F$12)*'Вводные'!$F$13 -> 4500 | I6: =MIN('Вводные'!$F$10+(I$2-1)*'Вводные'!$F$11,'Вводные'!$F$12)*'Вводные'!$F$13 -> 4800 | J6: =MIN('Вводные'!$F$10+(J$2-1)*'Вводные'!$F$11,'Вводные'!$F$12)*'Вводные'!$F$13 -> 5100 | ... AL6: =MIN('Вводные'!$F$10+(AL$2-1)*'Вводные'!$F$11,'Вводные'!$F$12)*'Вводные'!$F$13 -> 6000 | AM6: =AVERAGE(C6:N6) -> 4625 | AN6: =AVERAGE(O6:Z6) -> 6000 | AO6: =AVERAGE(AA6:AL6) -> 6000 | AP6: =AVERAGE(C6:AL6) -> 5541.6667
B7: Среднее кол-во чеков/день | C7: =MIN('Вводные'!$F$10+(C$2-1)*'Вводные'!$F$11,'Вводные'!$F$12) -> 100 | D7: =MIN('Вводные'!$F$10+(D$2-1)*'Вводные'!$F$11,'Вводные'!$F$12) -> 110 | E7: =MIN('Вводные'!$F$10+(E$2-1)*'Вводные'!$F$11,'Вводные'!$F$12) -> 120 | F7: =MIN('Вводные'!$F$10+(F$2-1)*'Вводные'!$F$11,'Вводные'!$F$12) -> 130 | G7: =MIN('Вводные'!$F$10+(G$2-1)*'Вводные'!$F$11,'Вводные'!$F$12) -> 140 | H7: =MIN('Вводные'!$F$10+(H$2-1)*'Вводные'!$F$11,'Вводные'!$F$12) -> 150 | I7: =MIN('Вводные'!$F$10+(I$2-1)*'Вводные'!$F$11,'Вводные'!$F$12) -> 160 | J7: =MIN('Вводные'!$F$10+(J$2-1)*'Вводные'!$F$11,'Вводные'!$F$12) -> 170 | ... AL7: =MIN('Вводные'!$F$10+(AL$2-1)*'Вводные'!$F$11,'Вводные'!$F$12) -> 200
B9: РАСХОДЫ (без налогов) | C9: =C10+C17 -> 1568358 | D9: =D10+D17 -> 1638518 | E9: =E10+E17 -> 1708678 | F9: =F10+F17 -> 1773838 | G9: =G10+G17 -> 1838998 | H9: =H10+H17 -> 1904158 | I9: =I10+I17 -> 1969318 | J9: =J10+J17 -> 2034478 | ... AL9: =AL10+AL17 -> 2229958 | AM9: =SUM(C9:N9) -> 23160696 | AN9: =SUM(O9:Z9) -> 26759496 | AO9: =SUM(AA9:AL9) -> 26759496 | AP9: =SUM(AM9:AO9) -> 76679688
B10: Переменные расходы | C10: =C11+C12+C13+C14+C15 -> 676600 | D10: =D11+D12+D13+D14+D15 -> 746760 | E10: =E11+E12+E13+E14+E15 -> 816920 | F10: =F11+F12+F13+F14+F15 -> 882080 | G10: =G11+G12+G13+G14+G15 -> 947240 | H10: =H11+H12+H13+H14+H15 -> 1012400 | I10: =I11+I12+I13+I14+I15 -> 1077560 | J10: =J11+J12+J13+J14+J15 -> 1142720 | ... AL10: =AL11+AL12+AL13+AL14+AL15 -> 1338200 | AM10: =SUM(C10:N10) -> 12459600 | AN10: =SUM(O10:Z10) -> 16058400 | AO10: =SUM(AA10:AL10) -> 16058400 | AP10: =SUM(AM10:AO10) -> 44576400
B11: ФОТ переменная (техник + премии) | C11: ='Вводные'!$F$22+MIN(IF(C$2=1,0,(C$2-1)*'Вводные'!$F$23),'Вводные'!$F$24) -> 5000 | D11: ='Вводные'!$F$22+MIN(IF(D$2=1,0,(D$2-1)*'Вводные'!$F$23),'Вводные'!$F$24) -> 10000 | E11: ='Вводные'!$F$22+MIN(IF(E$2=1,0,(E$2-1)*'Вводные'!$F$23),'Вводные'!$F$24) -> 15000 | F11: ='Вводные'!$F$22+MIN(IF(F$2=1,0,(F$2-1)*'Вводные'!$F$23),'Вводные'!$F$24) -> 15000 | G11: ='Вводные'!$F$22+MIN(IF(G$2=1,0,(G$2-1)*'Вводные'!$F$23),'Вводные'!$F$24) -> 15000 | H11: ='Вводные'!$F$22+MIN(IF(H$2=1,0,(H$2-1)*'Вводные'!$F$23),'Вводные'!$F$24) -> 15000 | I11: ='Вводные'!$F$22+MIN(IF(I$2=1,0,(I$2-1)*'Вводные'!$F$23),'Вводные'!$F$24) -> 15000 | J11: ='Вводные'!$F$22+MIN(IF(J$2=1,0,(J$2-1)*'Вводные'!$F$23),'Вводные'!$F$24) -> 15000 | ... AL11: ='Вводные'!$F$22+MIN(IF(AL$2=1,0,(AL$2-1)*'Вводные'!$F$23),'Вводные'!$F$24) -> 15000 | AM11: =SUM(C11:N11) -> 165000 | AN11: =SUM(O11:Z11) -> 180000 | AO11: =SUM(AA11:AL11) -> 180000 | AP11: =SUM(AM11:AO11) -> 525000
B12: Себестоимость продуктов (COGS 30%) | C12: =C4*'Вводные'!$F$16 -> 540000 | D12: =D4*'Вводные'!$F$16 -> 594000 | E12: =E4*'Вводные'!$F$16 -> 648000 | F12: =F4*'Вводные'!$F$16 -> 702000 | G12: =G4*'Вводные'!$F$16 -> 756000 | H12: =H4*'Вводные'!$F$16 -> 810000 | I12: =I4*'Вводные'!$F$16 -> 864000 | J12: =J4*'Вводные'!$F$16 -> 918000 | ... AL12: =AL4*'Вводные'!$F$16 -> 1080000 | AM12: =SUM(C12:N12) -> 9990000 | AN12: =SUM(O12:Z12) -> 12960000 | AO12: =SUM(AA12:AL12) -> 12960000 | AP12: =SUM(AM12:AO12) -> 35910000
B13: Эквайринг (80% безнала × 1.5%) | C13: =C4*0.8*'Вводные'!$F$17 -> 21600 | D13: =D4*0.8*'Вводные'!$F$17 -> 23760 | E13: =E4*0.8*'Вводные'!$F$17 -> 25920 | F13: =F4*0.8*'Вводные'!$F$17 -> 28080 | G13: =G4*0.8*'Вводные'!$F$17 -> 30240 | H13: =H4*0.8*'Вводные'!$F$17 -> 32400 | I13: =I4*0.8*'Вводные'!$F$17 -> 34560 | J13: =J4*0.8*'Вводные'!$F$17 -> 36720 | ... AL13: =AL4*0.8*'Вводные'!$F$17 -> 43200 | AM13: =SUM(C13:N13) -> 399600 | AN13: =SUM(O13:Z13) -> 518400 | AO13: =SUM(AA13:AL13) -> 518400 | AP13: =SUM(AM13:AO13) -> 1436400
B14: Расходные материалы | C14: ='Вводные'!$F$25 -> 20000 | D14: ='Вводные'!$F$25 -> 20000 | E14: ='Вводные'!$F$25 -> 20000 | F14: ='Вводные'!$F$25 -> 20000 | G14: ='Вводные'!$F$25 -> 20000 | H14: ='Вводные'!$F$25 -> 20000 | I14: ='Вводные'!$F$25 -> 20000 | J14: ='Вводные'!$F$25 -> 20000 | ... AL14: ='Вводные'!$F$25 -> 20000 | AM14: =SUM(C14:N14) -> 240000 | AN14: =SUM(O14:Z14) -> 240000 | AO14: =SUM(AA14:AL14) -> 240000 | AP14: =SUM(AM14:AO14) -> 720000
B15: Маркетинг (2% от выручки) | C15: =C4*'Вводные'!$F$18 -> 90000 | D15: =D4*'Вводные'!$F$18 -> 99000 | E15: =E4*'Вводные'!$F$18 -> 108000 | F15: =F4*'Вводные'!$F$18 -> 117000 | G15: =G4*'Вводные'!$F$18 -> 126000 | H15: =H4*'Вводные'!$F$18 -> 135000 | I15: =I4*'Вводные'!$F$18 -> 144000 | J15: =J4*'Вводные'!$F$18 -> 153000 | ... AL15: =AL4*'Вводные'!$F$18 -> 180000 | AM15: =SUM(C15:N15) -> 1665000 | AN15: =SUM(O15:Z15) -> 2160000 | AO15: =SUM(AA15:AL15) -> 2160000 | AP15: =SUM(AM15:AO15) -> 5985000
B17: Постоянные расходы | C17: =C18+C19+C20+C21+C22+C23+C28+C29+C30 -> 891758 | D17: =D18+D19+D20+D21+D22+D23+D28+D29+D30 -> 891758 | E17: =E18+E19+E20+E21+E22+E23+E28+E29+E30 -> 891758 | F17: =F18+F19+F20+F21+F22+F23+F28+F29+F30 -> 891758 | G17: =G18+G19+G20+G21+G22+G23+G28+G29+G30 -> 891758 | H17: =H18+H19+H20+H21+H22+H23+H28+H29+H30 -> 891758 | I17: =I18+I19+I20+I21+I22+I23+I28+I29+I30 -> 891758 | J17: =J18+J19+J20+J21+J22+J23+J28+J29+J30 -> 891758 | ... AL17: =AL18+AL19+AL20+AL21+AL22+AL23+AL28+AL29+AL30 -> 891758 | AM17: =SUM(C17:N17) -> 10701096 | AN17: =SUM(O17:Z17) -> 10701096 | AO17: =SUM(AA17:AL17) -> 10701096 | AP17: =SUM(AM17:AO17) -> 32103288
B18: Аренда | C18: ='Вводные'!$F28 -> 220000 | D18: ='Вводные'!$F28 -> 220000 | E18: ='Вводные'!$F28 -> 220000 | F18: ='Вводные'!$F28 -> 220000 | G18: ='Вводные'!$F28 -> 220000 | H18: ='Вводные'!$F28 -> 220000 | I18: ='Вводные'!$F28 -> 220000 | J18: ='Вводные'!$F28 -> 220000 | ... AL18: ='Вводные'!$F28 -> 220000 | AM18: =SUM(C18:N18) -> 2640000 | AN18: =SUM(O18:Z18) -> 2640000 | AO18: =SUM(AA18:AL18) -> 2640000 | AP18: =SUM(AM18:AO18) -> 7920000
B19: Коммуналка | C19: ='Вводные'!$F29 -> 50000 | D19: ='Вводные'!$F29 -> 50000 | E19: ='Вводные'!$F29 -> 50000 | F19: ='Вводные'!$F29 -> 50000 | G19: ='Вводные'!$F29 -> 50000 | H19: ='Вводные'!$F29 -> 50000 | I19: ='Вводные'!$F29 -> 50000 | J19: ='Вводные'!$F29 -> 50000 | ... AL19: ='Вводные'!$F29 -> 50000 | AM19: =SUM(C19:N19) -> 600000 | AN19: =SUM(O19:Z19) -> 600000 | AO19: =SUM(AA19:AL19) -> 600000 | AP19: =SUM(AM19:AO19) -> 1800000
B20: П.О. (программное обеспечение) | C20: ='Вводные'!$F30 -> 6658 | D20: ='Вводные'!$F30 -> 6658 | E20: ='Вводные'!$F30 -> 6658 | F20: ='Вводные'!$F30 -> 6658 | G20: ='Вводные'!$F30 -> 6658 | H20: ='Вводные'!$F30 -> 6658 | I20: ='Вводные'!$F30 -> 6658 | J20: ='Вводные'!$F30 -> 6658 | ... AL20: ='Вводные'!$F30 -> 6658 | AM20: =SUM(C20:N20) -> 79896 | AN20: =SUM(O20:Z20) -> 79896 | AO20: =SUM(AA20:AL20) -> 79896 | AP20: =SUM(AM20:AO20) -> 239688
B21: Охранная система | C21: ='Вводные'!$F31 -> 3500 | D21: ='Вводные'!$F31 -> 3500 | E21: ='Вводные'!$F31 -> 3500 | F21: ='Вводные'!$F31 -> 3500 | G21: ='Вводные'!$F31 -> 3500 | H21: ='Вводные'!$F31 -> 3500 | I21: ='Вводные'!$F31 -> 3500 | J21: ='Вводные'!$F31 -> 3500 | ... AL21: ='Вводные'!$F31 -> 3500 | AM21: =SUM(C21:N21) -> 42000 | AN21: =SUM(O21:Z21) -> 42000 | AO21: =SUM(AA21:AL21) -> 42000 | AP21: =SUM(AM21:AO21) -> 126000
B22: Связь / интернет | C22: ='Вводные'!$F32 -> 2000 | D22: ='Вводные'!$F32 -> 2000 | E22: ='Вводные'!$F32 -> 2000 | F22: ='Вводные'!$F32 -> 2000 | G22: ='Вводные'!$F32 -> 2000 | H22: ='Вводные'!$F32 -> 2000 | I22: ='Вводные'!$F32 -> 2000 | J22: ='Вводные'!$F32 -> 2000 | ... AL22: ='Вводные'!$F32 -> 2000 | AM22: =SUM(C22:N22) -> 24000 | AN22: =SUM(O22:Z22) -> 24000 | AO22: =SUM(AA22:AL22) -> 24000 | AP22: =SUM(AM22:AO22) -> 72000
B23: Постоянная часть ФОТ | C23: ='Вводные'!$F33 -> 440000 | D23: ='Вводные'!$F33 -> 440000 | E23: ='Вводные'!$F33 -> 440000 | F23: ='Вводные'!$F33 -> 440000 | G23: ='Вводные'!$F33 -> 440000 | H23: ='Вводные'!$F33 -> 440000 | I23: ='Вводные'!$F33 -> 440000 | J23: ='Вводные'!$F33 -> 440000 | ... AL23: ='Вводные'!$F33 -> 440000 | AM23: =SUM(C23:N23) -> 5280000 | AN23: =SUM(O23:Z23) -> 5280000 | AO23: =SUM(AA23:AL23) -> 5280000 | AP23: =SUM(AM23:AO23) -> 15840000
B24: Бариста-кассира (2×80 000) | C24: ='Вводные'!$F34 -> 160000 | D24: ='Вводные'!$F34 -> 160000 | E24: ='Вводные'!$F34 -> 160000 | F24: ='Вводные'!$F34 -> 160000 | G24: ='Вводные'!$F34 -> 160000 | H24: ='Вводные'!$F34 -> 160000 | I24: ='Вводные'!$F34 -> 160000 | J24: ='Вводные'!$F34 -> 160000 | ... AL24: ='Вводные'!$F34 -> 160000 | AM24: =SUM(C24:N24) -> 1920000 | AN24: =SUM(O24:Z24) -> 1920000 | AO24: =SUM(AA24:AL24) -> 1920000 | AP24: =SUM(AM24:AO24) -> 5760000
B25: Повар (2×120 000) | C25: ='Вводные'!$F35 -> 240000 | D25: ='Вводные'!$F35 -> 240000 | E25: ='Вводные'!$F35 -> 240000 | F25: ='Вводные'!$F35 -> 240000 | G25: ='Вводные'!$F35 -> 240000 | H25: ='Вводные'!$F35 -> 240000 | I25: ='Вводные'!$F35 -> 240000 | J25: ='Вводные'!$F35 -> 240000 | ... AL25: ='Вводные'!$F35 -> 240000 | AM25: =SUM(C25:N25) -> 2880000 | AN25: =SUM(O25:Z25) -> 2880000 | AO25: =SUM(AA25:AL25) -> 2880000 | AP25: =SUM(AM25:AO25) -> 8640000
B26: Менеджер | C26: ='Вводные'!$F36 -> 40000 | D26: ='Вводные'!$F36 -> 40000 | E26: ='Вводные'!$F36 -> 40000 | F26: ='Вводные'!$F36 -> 40000 | G26: ='Вводные'!$F36 -> 40000 | H26: ='Вводные'!$F36 -> 40000 | I26: ='Вводные'!$F36 -> 40000 | J26: ='Вводные'!$F36 -> 40000 | ... AL26: ='Вводные'!$F36 -> 40000 | AM26: =SUM(C26:N26) -> 480000 | AN26: =SUM(O26:Z26) -> 480000 | AO26: =SUM(AA26:AL26) -> 480000 | AP26: =SUM(AM26:AO26) -> 1440000
B28: Налоги/платежи за сотрудников | C28: ='Вводные'!$F37 -> 149600 | D28: ='Вводные'!$F37 -> 149600 | E28: ='Вводные'!$F37 -> 149600 | F28: ='Вводные'!$F37 -> 149600 | G28: ='Вводные'!$F37 -> 149600 | H28: ='Вводные'!$F37 -> 149600 | I28: ='Вводные'!$F37 -> 149600 | J28: ='Вводные'!$F37 -> 149600 | ... AL28: ='Вводные'!$F37 -> 149600 | AM28: =SUM(C28:N28) -> 1795200 | AN28: =SUM(O28:Z28) -> 1795200 | AO28: =SUM(AA28:AL28) -> 1795200 | AP28: =SUM(AM28:AO28) -> 5385600
B29: Уборщица аутсорс | C29: ='Вводные'!$F38 -> 0 | D29: ='Вводные'!$F38 -> 0 | E29: ='Вводные'!$F38 -> 0 | F29: ='Вводные'!$F38 -> 0 | G29: ='Вводные'!$F38 -> 0 | H29: ='Вводные'!$F38 -> 0 | I29: ='Вводные'!$F38 -> 0 | J29: ='Вводные'!$F38 -> 0 | ... AL29: ='Вводные'!$F38 -> 0 | AM29: =SUM(C29:N29) -> 0 | AN29: =SUM(O29:Z29) -> 0 | AO29: =SUM(AA29:AL29) -> 0 | AP29: =SUM(AM29:AO29) -> 0
B30: Бухгалтер | C30: ='Вводные'!$F39 -> 20000 | D30: ='Вводные'!$F39 -> 20000 | E30: ='Вводные'!$F39 -> 20000 | F30: ='Вводные'!$F39 -> 20000 | G30: ='Вводные'!$F39 -> 20000 | H30: ='Вводные'!$F39 -> 20000 | I30: ='Вводные'!$F39 -> 20000 | J30: ='Вводные'!$F39 -> 20000 | ... AL30: ='Вводные'!$F39 -> 20000 | AM30: =SUM(C30:N30) -> 240000 | AN30: =SUM(O30:Z30) -> 240000 | AO30: =SUM(AA30:AL30) -> 240000 | AP30: =SUM(AM30:AO30) -> 720000
B32: Налоги (УСН/патент) | C32: ='Вводные'!$F$42 -> 25000 | D32: ='Вводные'!$F$42 -> 25000 | E32: ='Вводные'!$F$42 -> 25000 | F32: ='Вводные'!$F$42 -> 25000 | G32: ='Вводные'!$F$42 -> 25000 | H32: ='Вводные'!$F$42 -> 25000 | I32: ='Вводные'!$F$42 -> 25000 | J32: ='Вводные'!$F$42 -> 25000 | ... AL32: ='Вводные'!$F$42 -> 25000 | AM32: =SUM(C32:N32) -> 300000 | AN32: =SUM(O32:Z32) -> 300000 | AO32: =SUM(AA32:AL32) -> 300000 | AP32: =SUM(AM32:AO32) -> 900000
B34: ЧИСТАЯ ПРИБЫЛЬ | C34: =C4-C9-C32 -> 206642 | D34: =D4-D9-D32 -> 316482 | E34: =E4-E9-E32 -> 426322 | F34: =F4-F9-F32 -> 541162 | G34: =G4-G9-G32 -> 656002 | H34: =H4-H9-H32 -> 770842 | I34: =I4-I9-I32 -> 885682 | J34: =J4-J9-J32 -> 1000522 | ... AL34: =AL4-AL9-AL32 -> 1345042 | AM34: =SUM(C34:N34) -> 9839304 | AN34: =SUM(O34:Z34) -> 16140504 | AO34: =SUM(AA34:AL34) -> 16140504 | AP34: =SUM(AM34:AO34) -> 42120312
B35: Рентабельность, % | C35: =IFERROR(C34/C4,0) -> 0.11480111 | D35: =IFERROR(D34/D4,0) -> 0.15983939 | E35: =IFERROR(E34/E4,0) -> 0.1973713 | F35: =IFERROR(F34/F4,0) -> 0.23126581 | G35: =IFERROR(G34/G4,0) -> 0.26031825 | H35: =IFERROR(H34/H4,0) -> 0.28549704 | I35: =IFERROR(I34/I4,0) -> 0.30752847 | J35: =IFERROR(J34/J4,0) -> 0.32696797 | ... AL35: =IFERROR(AL34/AL4,0) -> 0.37362278 | AM35: =IFERROR(SUM(C34:N34)/SUM(C4:N4),0) -> 0.29547459 | AN35: =IFERROR(SUM(O34:Z34)/SUM(O4:Z4),0) -> 0.37362278 | AO35: =IFERROR(SUM(AA34:AL34)/SUM(AA4:AL4),0) -> 0.37362278 | AP35: =IFERROR(AP34/AP4,0) -> 0.35188231
B37: Точка возврата инвестиций (нарастающий итог) | C37: =-'Вводные'!$F$48+C34 -> -4435669 | D37: =C37+D34 -> -4119187 | E37: =D37+E34 -> -3692865 | F37: =E37+F34 -> -3151703 | G37: =F37+G34 -> -2495701 | H37: =G37+H34 -> -1724859 | I37: =H37+I34 -> -839177 | J37: =I37+J34 -> 161345 | K37: =J37+K34 -> 1276707 | ... AL37: =AK37+AL34 -> 37478001 | AM37: =N37 -> 5196993 | AN37: =Z37 -> 21337497 | AO37: =AL37 -> 37478001 | AP37: =AL37 -> 37478001
B38: Точка безубыточности (ежемес.), руб. | C38: =(C11+C14+C17+C32)/(1-'Вводные'!$F$16-0.8*'Вводные'!$F$17-'Вводные'!$F$18) -> 1476109.7 | D38: =(D11+D14+D17+D32)/(1-'Вводные'!$F$16-0.8*'Вводные'!$F$17-'Вводные'!$F$18) -> 1483946.7 | E38: =(E11+E14+E17+E32)/(1-'Вводные'!$F$16-0.8*'Вводные'!$F$17-'Вводные'!$F$18) -> 1491783.7 | F38: =(F11+F14+F17+F32)/(1-'Вводные'!$F$16-0.8*'Вводные'!$F$17-'Вводные'!$F$18) -> 1491783.7 | G38: =(G11+G14+G17+G32)/(1-'Вводные'!$F$16-0.8*'Вводные'!$F$17-'Вводные'!$F$18) -> 1491783.7 | H38: =(H11+H14+H17+H32)/(1-'Вводные'!$F$16-0.8*'Вводные'!$F$17-'Вводные'!$F$18) -> 1491783.7 | I38: =(I11+I14+I17+I32)/(1-'Вводные'!$F$16-0.8*'Вводные'!$F$17-'Вводные'!$F$18) -> 1491783.7 | J38: =(J11+J14+J17+J32)/(1-'Вводные'!$F$16-0.8*'Вводные'!$F$17-'Вводные'!$F$18) -> 1491783.7 | ... AL38: =(AL11+AL14+AL17+AL32)/(1-'Вводные'!$F$16-0.8*'Вводные'!$F$17-'Вводные'!$F$18) -> 1491783.7

Sheet Инвест.бюджет
B1: ИНВЕСТИЦИОННЫЙ БЮДЖЕТ
B2: =IF('Вводные'!C5=1,"Сценарий: Оптимистичный",IF('Вводные'!C5=2,"Сценарий: Реалистичный","Сценарий: Пессимистичный")) -> Сценарий: Реалистичный
B4: Статья бюджета | C4: Ед. | D4: Кол-во | E4: Стоимость, руб. | F4: Примечание
B5: РЕГИСТРАЦИЯ | E5: 550
B6: ЭЦП + Печать | C6: шт. | D6: 1 | E6: 550 | F6: Госпошлина = 0 (онлайн)
B7: БРЕНДИРОВАНИЕ | E7: 0
B8: Логотип, фирмстиль, меню | C8: компл. | D8: 1 | E8: 0 | F8: Выполнено без затрат
B9: ПО + КАССОВОЕ ОБОРУДОВАНИЕ | E9: 41658
B10: Онлайн-касса + настройка | C10: шт. | D10: 1 | E10: 35000
B11: П.О. (программное обеспечение) | C11: мес. | D11: 1 | E11: 6658
B12: АРЕНДА (1-й мес.) | E12: 270000
B13: Аренда 1-й месяц | C13: мес. | D13: 1 | E13: 220000
B14: Коммуналка 1-й мес. | C14: мес. | D14: 1 | E14: 50000
B15: ПОМЕЩЕНИЕ (ремонт) | E15: 1525500
B16: Дизайн-проект | C16: м² | D16: 100 | E16: 200000 | F16: 2 000 руб/м²
B17: Ремонтные работы | C17: м² | D17: 100 | E17: 900000 | F17: 9 000 руб/м²
B18: Материалы | C18: компл. | D18: 1 | E18: 150000
B19: Паспорта на вывоз мусора | C19: шт. | D19: 1 | E19: 15000
B20: Пожарная безопасность | C20: компл. | D20: 1 | E20: 5000
B21: Охрана (первоначальный взнос) | C21: компл. | D21: 1 | E21: 3500
B22: Интернет + роутер | C22: компл. | D22: 1 | E22: 2000
B23: Барная стойка (полки, сантехника) | C23: компл. | D23: 1 | E23: 200000
B24: Вывеска | C24: шт. | D24: 1 | E24: 50000
B25: МЕБЕЛЬ | E25: 436000
B26: Стулья/кресла (20 шт × 6 000) | C26: шт. | D26: 20 | E26: 120000
B27: Столы (15 шт × 10 000) | C27: шт. | D27: 15 | E27: 150000
B28: Пианино | C28: шт. | D28: 1 | E28: 70000 | F28: Б/у
B29: Диваны (8 шт × 12 000) | C29: шт. | D29: 8 | E29: 96000
B30: ОБОРУДОВАНИЕ | E30: 1037013
B31: Кухонное + кофейное оборудование | C31: компл. | D31: 1 | E31: 1037013 | F31: Искать б/у
B32: ИНВЕНТАРЬ | E32: 51930
B33: Инвентарь | C33: компл. | D33: 1 | E33: 51930 | F33: Максимально дешёвое
B34: ПОСУДА | E34: 61010
B35: Посуда (тарелки, кружки, стаканы) | C35: компл. | D35: 1 | E35: 52540 | F35: Не покупать дорогую сразу
B36: Одноразовая посуда (15–30 дней) | C36: компл. | D36: 1 | E36: 9470
B37: ФОТ НА 1-Й МЕС. | E37: 578950
B38: Бариста×2, Повар×2, Менеджер, Бухг, Техник + налоги | C38: компл. | D38: 1 | E38: 578950
B39: ПРОЧИЕ РАСХОДЫ | E39: 100000
B40: Расходные материалы, химия, мелочи | C40: компл. | D40: 1 | E40: 100000
B41: МАРКЕТИНГ (открытие) | E41: 20000
...
