Workbook

Sheet Калькулятор инвестора
B1: LUCE SILVA — КАЛЬКУЛЯТОР ДОХОДНОСТИ ИНВЕСТОРА
B2: Введите сумму — и увидите свой доход в 2027, 2028, 2029 году и стоимость доли при продаже
B4: ВАШ ВКЛАД В ПРОЕКТ | C4: МИН (80 свадеб) | D4: БАЗОВЫЙ (100) | E4: МАКС (150)
B5: 💰 Ваша сумма инвестиций | C5: 1000000 | D5: ← МЕНЯЙТЕ ЭТУ ЯЧЕЙКУ
B6: Ваша доля в проекте | C6: =C5/Допущения!C5*Допущения!C6 -> 0.0074242424
B7: Ваша доля в пуле инвесторов (от 66 млн ₽) | C7: =C5/Допущения!C5 -> 0.015151515
B8: Минимальный чек входа в раунд | C8: =Допущения!C8 -> 1000000
B10: ПОКАЗАТЕЛЬ | C10: 📉 МИНИМАЛЬНЫЙ 80 свадеб | D10: 📊 БАЗОВЫЙ 100 свадеб | E10: 📈 МАКСИМАЛЬНЫЙ 120 свадеб
B11: ДИВИДЕНДНЫЙ ДОХОД ПО ГОДАМ — ВАШ ЛИЧНЫЙ РАСЧЁТ
B13: 📅 2027 год — первый сезон (май–октябрь) | C13: Механика: 80% прибыли | D13: Механика: 80% прибыли | E13: Механика: 80% прибыли
B14: Прибыль проекта за сезон | C14: =Сценарии!C7 -> 52.72 | D14: =Сценарии!D7 -> 65.9 | E14: =Сценарии!E7 -> 79.08
B15: Пул дивидендов (80% → все инвесторы) | C15: =Сценарии!C8 -> 42.176 | D15: =Сценарии!D8 -> 52.72 | E15: =Сценарии!E8 -> 63.264
B16: 💵 Ваш доход в 2029 году | C16: =Сценарии!C7*1000000*Допущения!C7*(C5/Допущения!C5) -> 639030.3 | D16: =Сценарии!D7*1000000*Допущения!C7*(C5/Допущения!C5) -> 798787.88 | E16: =Сценарии!E7*1000000*Допущения!C7*(C5/Допущения!C5) -> 958545.45
B17: Доходность за год | C17: =(Сценарии!C7*1000000*Допущения!C7*(C5/Допущения!C5))/C5 -> 0.6390303 | D17: =(Сценарии!D7*1000000*Допущения!C7*(C5/Допущения!C5))/C5 -> 0.79878788 | E17: =(Сценарии!E7*1000000*Допущения!C7*(C5/Допущения!C5))/C5 -> 0.95854545
B19: 📅 2028 год — второй сезон (май–октябрь) | C19: 80% (ещё в возврате) | D19: 80%→49% (переход) | E19: 49% (возврат завершён)
B20: Прибыль проекта за сезон | C20: =Сценарии!C7 -> 52.72 | D20: =Сценарии!D7 -> 65.9 | E20: =Сценарии!E7 -> 79.08
B21: 💵 Ваш доход в 2027 году | C21: =IF(MAX(0,Допущения!C5-Сценарии!C7*1000000*Допущения!C7)=0,Сценарии!C7*1000000*Допущения!C6,IF(MAX(0,Допущения!C5-Сценарии!C7*1000000*Допущения!C7)>=Сценарии!C7*1000000*Допущения!C7,Сценарии!C7*1000000*Допущения!C7,MAX(0,Допущения!C5-Сценарии!C7*1000000*Допущения!C7)+(Сценарии!C7*1000000-MAX(0,Допущения!C5-Сценарии!C7*1000000*Допущения!C7)/Допущения!C7)*Допущения!C6))*(C5/Допущения!C5) -> 531281.82 | D21: =IF(MAX(0,Допущения!C5-Сценарии!D7*1000000*Допущения!C7)=0,Сценарии!D7*1000000*Допущения!C6,IF(MAX(0,Допущения!C5-Сценарии!D7*1000000*Допущения!C7)>=Сценарии!D7*1000000*Допущения!C7,Сценарии!D7*1000000*Допущения!C7,MAX(0,Допущения!C5-Сценарии!D7*1000000*Допущения!C7)+(Сценарии!D7*1000000-MAX(0,Допущения!C5-Сценарии!D7*1000000*Допущения!C7)/Допущения!C7)*Допущения!C6))*(C5/Допущения!C5) -> 567227.27 | E21: =IF(MAX(0,Допущения!C5-Сценарии!E7*1000000*Допущения!C7)=0,Сценарии!E7*1000000*Допущения!C6,IF(MAX(0,Допущения!C5-Сценарии!E7*1000000*Допущения!C7)>=Сценарии!E7*1000000*Допущения!C7,Сценарии!E7*1000000*Допущения!C7,MAX(0,Допущения!C5-Сценарии!E7*1000000*Допущения!C7)+(Сценарии!E7*1000000-MAX(0,Допущения!C5-Сценарии!E7*1000000*Допущения!C7)/Допущения!C7)*Допущения!C6))*(C5/Допущения!C5) -> 603172.73
B22: Доходность за год | C22: =(IF(MAX(0,Допущения!C5-Сценарии!C7*1000000*Допущения!C7)=0,Сценарии!C7*1000000*Допущения!C6,IF(MAX(0,Допущения!C5-Сценарии!C7*1000000*Допущения!C7)>=Сценарии!C7*1000000*Допущения!C7,Сценарии!C7*1000000*Допущения!C7,MAX(0,Допущения!C5-Сценарии!C7*1000000*Допущения!C7)+(Сценарии!C7*1000000-MAX(0,Допущения!C5-Сценарии!C7*1000000*Допущения!C7)/Допущения!C7)*Допущения!C6))*(C5/Допущения!C5))/C5 -> 0.53128182 | D22: =(IF(MAX(0,Допущения!C5-Сценарии!D7*1000000*Допущения!C7)=0,Сценарии!D7*1000000*Допущения!C6,IF(MAX(0,Допущения!C5-Сценарии!D7*1000000*Допущения!C7)>=Сценарии!D7*1000000*Допущения!C7,Сценарии!D7*1000000*Допущения!C7,MAX(0,Допущения!C5-Сценарии!D7*1000000*Допущения!C7)+(Сценарии!D7*1000000-MAX(0,Допущения!C5-Сценарии!D7*1000000*Допущения!C7)/Допущения!C7)*Допущения!C6))*(C5/Допущения!C5))/C5 -> 0.56722727 | E22: =(IF(MAX(0,Допущения!C5-Сценарии!E7*1000000*Допущения!C7)=0,Сценарии!E7*1000000*Допущения!C6,IF(MAX(0,Допущения!C5-Сценарии!E7*1000000*Допущения!C7)>=Сценарии!E7*1000000*Допущения!C7,Сценарии!E7*1000000*Допущения!C7,MAX(0,Допущения!C5-Сценарии!E7*1000000*Допущения!C7)+(Сценарии!E7*1000000-MAX(0,Допущения!C5-Сценарии!E7*1000000*Допущения!C7)/Допущения!C7)*Допущения!C6))*(C5/Допущения!C5))/C5 -> 0.60317273
B24: 📅 2029 год — третий сезон (май–октябрь) | C24: 80%/49% (переход) | D24: 49% (стабильно) | E24: 49% (стабильно)
B25: Прибыль проекта за сезон | C25: =Сценарии!C7 -> 52.72 | D25: =Сценарии!D7 -> 65.9 | E25: =Сценарии!E7 -> 79.08
B26: 💵 Ваш доход в 2028 году | C26: =IF(MAX(0,MAX(0,Допущения!C5-Сценарии!C7*1000000*Допущения!C7)-IF(MAX(0,Допущения!C5-Сценарии!C7*1000000*Допущения!C7)=0,Сценарии!C7*1000000*Допущения!C6,IF(MAX(0,Допущения!C5-Сценарии!C7*1000000*Допущения!C7)>=Сценарии!C7*1000000*Допущения!C7,Сценарии!C7*1000000*Допущения!C7,MAX(0,Допущения!C5-Сценарии!C7*1000000*Допущения!C7)+(Сценарии!C7*1000000-MAX(0,Допущения!C5-Сценарии!C7*1000000*Допущения!C7)/Допущения!C7)*Допущения!C6)))=0,Сценарии!C7*1000000*Допущения!C6,IF(MAX(0,MAX(0,Допущения!C5-Сценарии!C7*1000000*Допущения!C7)-IF(MAX(0,Допущения!C5-Сценарии!C7*1000000*Допущения!C7)=0,Сценарии!C7*1000000*Допущения!C6,IF(MAX(0,Допущения!C5-Сценарии!C7*1000000*Допущения!C7)>=Сценарии!C7*1000000*Допущения!C7,Сценарии!C7*1000000*Допущения!C7,MAX(0,Допущения!C5-Сценарии!C7*1000000*Допущения!C7)+(Сценарии!C7*1000000-MAX(0,Допущения!C5-Сценарии!C7*1000000*Допущения!C7)/Допущения!C7)*Допущения!C6)))>=Сценарии!C7*1000000*Допущения!C7,Сценарии!C7*1000000*Допущения!C7,MAX(0,MAX(0,Допущения!C5-Сценарии!C7*1000000*Допущения!C7)-IF(MAX(0,Допущения!C5-Сценарии!C7*1000000*Допущения!C7)=0,Сценарии!C7*1000000*Допущения!C6,IF(MAX(0,Допущения!C5-Сценарии!C7*1000000*Допущения!C7)>=Сценарии!C7*1000000*Допущения!C7,Сценарии!C7*1000000*Допущения!C7,MAX(0,Допущения!C5-Сценарии!C7*1000000*Допущения!C7)+(Сценарии!C7*1000000-MAX(0,Допущения!C5-Сценарии!C7*1000000*Допущения!C7)/Допущения!C7)*Допущения!C6)))+(Сценарии!C7*1000000-MAX(0,MAX(0,Допущения!C5-Сценарии!C7*1000000*Допущения!C7)-IF(MAX(0,Допущения!C5-Сценарии!C7*1000000*Допущения!C7)=0,Сценарии!C7*1000000*Допущения!C6,IF(MAX(0,Допущения!C5-Сценарии!C7*1000000*Допущения!C7)>=Сценарии!C7*1000000*Допущения!C7,Сценарии!C7*1000000*Допущения!C7,MAX(0,Допущения!C5-Сценарии!C7*1000000*Допущения!C7)+(Сценарии!C7*1000000-MAX(0,Допущения!C5-Сценарии!C7*1000000*Допущения!C7)/Допущения!C7)*Допущения!C6)))/Допущения!C7)*Допущения!C6))*(C5/Допущения!C5) -> 391406.06 | D26: =IF(MAX(0,MAX(0,Допущения!C5-Сценарии!D7*1000000*Допущения!C7)-IF(MAX(0,Допущения!C5-Сценарии!D7*1000000*Допущения!C7)=0,Сценарии!D7*1000000*Допущения!C6,IF(MAX(0,Допущения!C5-Сценарии!D7*1000000*Допущения!C7)>=Сценарии!D7*1000000*Допущения!C7,Сценарии!D7*1000000*Допущения!C7,MAX(0,Допущения!C5-Сценарии!D7*1000000*Допущения!C7)+(Сценарии!D7*1000000-MAX(0,Допущения!C5-Сценарии!D7*1000000*Допущения!C7)/Допущения!C7)*Допущения!C6)))=0,Сценарии!D7*1000000*Допущения!C6,IF(MAX(0,MAX(0,Допущения!C5-Сценарии!D7*1000000*Допущения!C7)-IF(MAX(0,Допущения!C5-Сценарии!D7*1000000*Допущения!C7)=0,Сценарии!D7*1000000*Допущения!C6,IF(MAX(0,Допущения!C5-Сценарии!D7*1000000*Допущения!C7)>=Сценарии!D7*1000000*Допущения!C7,Сценарии!D7*1000000*Допущения!C7,MAX(0,Допущения!C5-Сценарии!D7*1000000*Допущения!C7)+(Сценарии!D7*1000000-MAX(0,Допущения!C5-Сценарии!D7*1000000*Допущения!C7)/Допущения!C7)*Допущения!C6)))>=Сценарии!D7*1000000*Допущения!C7,Сценарии!D7*1000000*Допущения!C7,MAX(0,MAX(0,Допущения!C5-Сценарии!D7*1000000*Допущения!C7)-IF(MAX(0,Допущения!C5-Сценарии!D7*1000000*Допущения!C7)=0,Сценарии!D7*1000000*Допущения!C6,IF(MAX(0,Допущения!C5-Сценарии!D7*1000000*Допущения!C7)>=Сценарии!D7*1000000*Допущения!C7,Сценарии!D7*1000000*Допущения!C7,MAX(0,Допущения!C5-Сценарии!D7*1000000*Допущения!C7)+(Сценарии!D7*1000000-MAX(0,Допущения!C5-Сценарии!D7*1000000*Допущения!C7)/Допущения!C7)*Допущения!C6)))+(Сценарии!D7*1000000-MAX(0,MAX(0,Допущения!C5-Сценарии!D7*1000000*Допущения!C7)-IF(MAX(0,Допущения!C5-Сценарии!D7*1000000*Допущения!C7)=0,Сценарии!D7*1000000*Допущения!C6,IF(MAX(0,Допущения!C5-Сценарии!D7*1000000*Допущения!C7)>=Сценарии!D7*1000000*Допущения!C7,Сценарии!D7*1000000*Допущения!C7,MAX(0,Допущения!C5-Сценарии!D7*1000000*Допущения!C7)+(Сценарии!D7*1000000-MAX(0,Допущения!C5-Сценарии!D7*1000000*Допущения!C7)/Допущения!C7)*Допущения!C6)))/Допущения!C7)*Допущения!C6))*(C5/Допущения!C5) -> 489257.58 | E26: =IF(MAX(0,MAX(0,Допущения!C5-Сценарии!E7*1000000*Допущения!C7)-IF(MAX(0,Допущения!C5-Сценарии!E7*1000000*Допущения!C7)=0,Сценарии!E7*1000000*Допущения!C6,IF(MAX(0,Допущения!C5-Сценарии!E7*1000000*Допущения!C7)>=Сценарии!E7*1000000*Допущения!C7,Сценарии!E7*1000000*Допущения!C7,MAX(0,Допущения!C5-Сценарии!E7*1000000*Допущения!C7)+(Сценарии!E7*1000000-MAX(0,Допущения!C5-Сценарии!E7*1000000*Допущения!C7)/Допущения!C7)*Допущения!C6)))=0,Сценарии!E7*1000000*Допущения!C6,IF(MAX(0,MAX(0,Допущения!C5-Сценарии!E7*1000000*Допущения!C7)-IF(MAX(0,Допущения!C5-Сценарии!E7*1000000*Допущения!C7)=0,Сценарии!E7*1000000*Допущения!C6,IF(MAX(0,Допущения!C5-Сценарии!E7*1000000*Допущения!C7)>=Сценарии!E7*1000000*Допущения!C7,Сценарии!E7*1000000*Допущения!C7,MAX(0,Допущения!C5-Сценарии!E7*1000000*Допущения!C7)+(Сценарии!E7*1000000-MAX(0,Допущения!C5-Сценарии!E7*1000000*Допущения!C7)/Допущения!C7)*Допущения!C6)))>=Сценарии!E7*1000000*Допущения!C7,Сценарии!E7*1000000*Допущения!C7,MAX(0,MAX(0,Допущения!C5-Сценарии!E7*1000000*Допущения!C7)-IF(MAX(0,Допущения!C5-Сценарии!E7*1000000*Допущения!C7)=0,Сценарии!E7*1000000*Допущения!C6,IF(MAX(0,Допущения!C5-Сценарии!E7*1000000*Допущения!C7)>=Сценарии!E7*1000000*Допущения!C7,Сценарии!E7*1000000*Допущения!C7,MAX(0,Допущения!C5-Сценарии!E7*1000000*Допущения!C7)+(Сценарии!E7*1000000-MAX(0,Допущения!C5-Сценарии!E7*1000000*Допущения!C7)/Допущения!C7)*Допущения!C6)))+(Сценарии!E7*1000000-MAX(0,MAX(0,Допущения!C5-Сценарии!E7*1000000*Допущения!C7)-IF(MAX(0,Допущения!C5-Сценарии!E7*1000000*Допущения!C7)=0,Сценарии!E7*1000000*Допущения!C6,IF(MAX(0,Допущения!C5-Сценарии!E7*1000000*Допущения!C7)>=Сценарии!E7*1000000*Допущения!C7,Сценарии!E7*1000000*Допущения!C7,MAX(0,Допущения!C5-Сценарии!E7*1000000*Допущения!C7)+(Сценарии!E7*1000000-MAX(0,Допущения!C5-Сценарии!E7*1000000*Допущения!C7)/Допущения!C7)*Допущения!C6)))/Допущения!C7)*Допущения!C6))*(C5/Допущения!C5) -> 587109.09
B27: Доходность за год | C27: =(IF(MAX(0,MAX(0,Допущения!C5-Сценарии!C7*1000000*Допущения!C7)-IF(MAX(0,Допущения!C5-Сценарии!C7*1000000*Допущения!C7)=0,Сценарии!C7*1000000*Допущения!C6,IF(MAX(0,Допущения!C5-Сценарии!C7*1000000*Допущения!C7)>=Сценарии!C7*1000000*Допущения!C7,Сценарии!C7*1000000*Допущения!C7,MAX(0,Допущения!C5-Сценарии!C7*1000000*Допущения!C7)+(Сценарии!C7*1000000-MAX(0,Допущения!C5-Сценарии!C7*1000000*Допущения!C7)/Допущения!C7)*Допущения!C6)))=0,Сценарии!C7*1000000*Допущения!C6,IF(MAX(0,MAX(0,Допущения!C5-Сценарии!C7*1000000*Допущения!C7)-IF(MAX(0,Допущения!C5-Сценарии!C7*1000000*Допущения!C7)=0,Сценарии!C7*1000000*Допущения!C6,IF(MAX(0,Допущения!C5-Сценарии!C7*1000000*Допущения!C7)>=Сценарии!C7*1000000*Допущения!C7,Сценарии!C7*1000000*Допущения!C7,MAX(0,Допущения!C5-Сценарии!C7*1000000*Допущения!C7)+(Сценарии!C7*1000000-MAX(0,Допущения!C5-Сценарии!C7*1000000*Допущения!C7)/Допущения!C7)*Допущения!C6)))>=Сценарии!C7*1000000*Допущения!C7,Сценарии!C7*1000000*Допущения!C7,MAX(0,MAX(0,Допущения!C5-Сценарии!C7*1000000*Допущения!C7)-IF(MAX(0,Допущения!C5-Сценарии!C7*1000000*Допущения!C7)=0,Сценарии!C7*1000000*Допущения!C6,IF(MAX(0,Допущения!C5-Сценарии!C7*1000000*Допущения!C7)>=Сценарии!C7*1000000*Допущения!C7,Сценарии!C7*1000000*Допущения!C7,MAX(0,Допущения!C5-Сценарии!C7*1000000*Допущения!C7)+(Сценарии!C7*1000000-MAX(0,Допущения!C5-Сценарии!C7*1000000*Допущения!C7)/Допущения!C7)*Допущения!C6)))+(Сценарии!C7*1000000-MAX(0,MAX(0,Допущения!C5-Сценарии!C7*1000000*Допущения!C7)-IF(MAX(0,Допущения!C5-Сценарии!C7*1000000*Допущения!C7)=0,Сценарии!C7*1000000*Допущения!C6,IF(MAX(0,Допущения!C5-Сценарии!C7*1000000*Допущения!C7)>=Сценарии!C7*1000000*Допущения!C7,Сценарии!C7*1000000*Допущения!C7,MAX(0,Допущения!C5-Сценарии!C7*1000000*Допущения!C7)+(Сценарии!C7*1000000-MAX(0,Допущения!C5-Сценарии!C7*1000000*Допущения!C7)/Допущения!C7)*Допущения!C6)))/Допущения!C7)*Допущения!C6))*(C5/Допущения!C5))/C5 -> 0.39140606 | D27: =(IF(MAX(0,MAX(0,Допущения!C5-Сценарии!D7*1000000*Допущения!C7)-IF(MAX(0,Допущения!C5-Сценарии!D7*1000000*Допущения!C7)=0,Сценарии!D7*1000000*Допущения!C6,IF(MAX(0,Допущения!C5-Сценарии!D7*1000000*Допущения!C7)>=Сценарии!D7*1000000*Допущения!C7,Сценарии!D7*1000000*Допущения!C7,MAX(0,Допущения!C5-Сценарии!D7*1000000*Допущения!C7)+(Сценарии!D7*1000000-MAX(0,Допущения!C5-Сценарии!D7*1000000*Допущения!C7)/Допущения!C7)*Допущения!C6)))=0,Сценарии!D7*1000000*Допущения!C6,IF(MAX(0,MAX(0,Допущения!C5-Сценарии!D7*1000000*Допущения!C7)-IF(MAX(0,Допущения!C5-Сценарии!D7*1000000*Допущения!C7)=0,Сценарии!D7*1000000*Допущения!C6,IF(MAX(0,Допущения!C5-Сценарии!D7*1000000*Допущения!C7)>=Сценарии!D7*1000000*Допущения!C7,Сценарии!D7*1000000*Допущения!C7,MAX(0,Допущения!C5-Сценарии!D7*1000000*Допущения!C7)+(Сценарии!D7*1000000-MAX(0,Допущения!C5-Сценарии!D7*1000000*Допущения!C7)/Допущения!C7)*Допущения!C6)))>=Сценарии!D7*1000000*Допущения!C7,Сценарии!D7*1000000*Допущения!C7,MAX(0,MAX(0,Допущения!C5-Сценарии!D7*1000000*Допущения!C7)-IF(MAX(0,Допущения!C5-Сценарии!D7*1000000*Допущения!C7)=0,Сценарии!D7*1000000*Допущения!C6,IF(MAX(0,Допущения!C5-Сценарии!D7*1000000*Допущения!C7)>=Сценарии!D7*1000000*Допущения!C7,Сценарии!D7*1000000*Допущения!C7,MAX(0,Допущения!C5-Сценарии!D7*1000000*Допущения!C7)+(Сценарии!D7*1000000-MAX(0,Допущения!C5-Сценарии!D7*1000000*Допущения!C7)/Допущения!C7)*Допущения!C6)))+(Сценарии!D7*1000000-MAX(0,MAX(0,Допущения!C5-Сценарии!D7*1000000*Допущения!C7)-IF(MAX(0,Допущения!C5-Сценарии!D7*1000000*Допущения!C7)=0,Сценарии!D7*1000000*Допущения!C6,IF(MAX(0,Допущения!C5-Сценарии!D7*1000000*Допущения!C7)>=Сценарии!D7*1000000*Допущения!C7,Сценарии!D7*1000000*Допущения!C7,MAX(0,Допущения!C5-Сценарии!D7*1000000*Допущения!C7)+(Сценарии!D7*1000000-MAX(0,Допущения!C5-Сценарии!D7*1000000*Допущения!C7)/Допущения!C7)*Допущения!C6)))/Допущения!C7)*Допущения!C6))*(C5/Допущения!C5))/C5 -> 0.48925758 | E27: =(IF(MAX(0,MAX(0,Допущения!C5-Сценарии!E7*1000000*Допущения!C7)-IF(MAX(0,Допущения!C5-Сценарии!E7*1000000*Допущения!C7)=0,Сценарии!E7*1000000*Допущения!C6,IF(MAX(0,Допущения!C5-Сценарии!E7*1000000*Допущения!C7)>=Сценарии!E7*1000000*Допущения!C7,Сценарии!E7*1000000*Допущения!C7,MAX(0,Допущения!C5-Сценарии!E7*1000000*Допущения!C7)+(Сценарии!E7*1000000-MAX(0,Допущения!C5-Сценарии!E7*1000000*Допущения!C7)/Допущения!C7)*Допущения!C6)))=0,Сценарии!E7*1000000*Допущения!C6,IF(MAX(0,MAX(0,Допущения!C5-Сценарии!E7*1000000*Допущения!C7)-IF(MAX(0,Допущения!C5-Сценарии!E7*1000000*Допущения!C7)=0,Сценарии!E7*1000000*Допущения!C6,IF(MAX(0,Допущения!C5-Сценарии!E7*1000000*Допущения!C7)>=Сценарии!E7*1000000*Допущения!C7,Сценарии!E7*1000000*Допущения!C7,MAX(0,Допущения!C5-Сценарии!E7*1000000*Допущения!C7)+(Сценарии!E7*1000000-MAX(0,Допущения!C5-Сценарии!E7*1000000*Допущения!C7)/Допущения!C7)*Допущения!C6)))>=Сценарии!E7*1000000*Допущения!C7,Сценарии!E7*1000000*Допущения!C7,MAX(0,MAX(0,Допущения!C5-Сценарии!E7*1000000*Допущения!C7)-IF(MAX(0,Допущения!C5-Сценарии!E7*1000000*Допущения!C7)=0,Сценарии!E7*1000000*Допущения!C6,IF(MAX(0,Допущения!C5-Сценарии!E7*1000000*Допущения!C7)>=Сценарии!E7*1000000*Допущения!C7,Сценарии!E7*1000000*Допущения!C7,MAX(0,Допущения!C5-Сценарии!E7*1000000*Допущения!C7)+(Сценарии!E7*1000000-MAX(0,Допущения!C5-Сценарии!E7*1000000*Допущения!C7)/Допущения!C7)*Допущения!C6)))+(Сценарии!E7*1000000-MAX(0,MAX(0,Допущения!C5-Сценарии!E7*1000000*Допущения!C7)-IF(MAX(0,Допущения!C5-Сценарии!E7*1000000*Допущения!C7)=0,Сценарии!E7*1000000*Допущения!C6,IF(MAX(0,Допущения!C5-Сценарии!E7*1000000*Допущения!C7)>=Сценарии!E7*1000000*Допущения!C7,Сценарии!E7*1000000*Допущения!C7,MAX(0,Допущения!C5-Сценарии!E7*1000000*Допущения!C7)+(Сценарии!E7*1000000-MAX(0,Допущения!C5-Сценарии!E7*1000000*Допущения!C7)/Допущения!C7)*Допущения!C6)))/Допущения!C7)*Допущения!C6))*(C5/Допущения!C5))/C5 -> 0.58710909
B29: ИТОГО ДИВИДЕНДОВ 2027–2029 | C29: =Сценарии!C7*1000000*Допущения!C7*(C5/Допущения!C5)+IF(MAX(0,Допущения!C5-Сценарии!C7*1000000*Допущения!C7)=0,Сценарии!C7*1000000*Допущения!C6,IF(MAX(0,Допущения!C5-Сценарии!C7*1000000*Допущения!C7)>=Сценарии!C7*1000000*Допущения!C7,Сценарии!C7*1000000*Допущения!C7,MAX(0,Допущения!C5-Сценарии!C7*1000000*Допущения!C7)+(Сценарии!C7*1000000-MAX(0,Допущения!C5-Сценарии!C7*1000000*Допущения!C7)/Допущения!C7)*Допущения!C6))*(C5/Допущения!C5)+IF(MAX(0,MAX(0,Допущения!C5-Сценарии!C7*1000000*Допущения!C7)-IF(MAX(0,Допущения!C5-Сценарии!C7*1000000*Допущения!C7)=0,Сценарии!C7*1000000*Допущения!C6,IF(MAX(0,Допущения!C5-Сценарии!C7*1000000*Допущения!C7)>=Сценарии!C7*1000000*Допущения!C7,Сценарии!C7*1000000*Допущения!C7,MAX(0,Допущения!C5-Сценарии!C7*1000000*Допущения!C7)+(Сценарии!C7*1000000-MAX(0,Допущения!C5-Сценарии!C7*1000000*Допущения!C7)/Допущения!C7)*Допущения!C6)))=0,Сценарии!C7*1000000*Допущения!C6,IF(MAX(0,MAX(0,Допущения!C5-Сценарии!C7*1000000*Допущения!C7)-IF(MAX(0,Допущения!C5-Сценарии!C7*1000000*Допущения!C7)=0,Сценарии!C7*1000000*Допущения!C6,IF(MAX(0,Допущения!C5-Сценарии!C7*1000000*Допущения!C7)>=Сценарии!C7*1000000*Допущения!C7,Сценарии!C7*1000000*Допущения!C7,MAX(0,Допущения!C5-Сценарии!C7*1000000*Допущения!C7)+(Сценарии!C7*1000000-MAX(0,Допущения!C5-Сценарии!C7*1000000*Допущения!C7)/Допущения!C7)*Допущения!C6)))>=Сценарии!C7*1000000*Допущения!C7,Сценарии!C7*1000000*Допущения!C7,MAX(0,MAX(0,Допущения!C5-Сценарии!C7*1000000*Допущения!C7)-IF(MAX(0,Допущения!C5-Сценарии!C7*1000000*Допущения!C7)=0,Сценарии!C7*1000000*Допущения!C6,IF(MAX(0,Допущения!C5-Сценарии!C7*1000000*Допущения!C7)>=Сценарии!C7*1000000*Допущения!C7,Сценарии!C7*1000000*Допущения!C7,MAX(0,Допущения!C5-Сценарии!C7*1000000*Допущения!C7)+(Сценарии!C7*1000000-MAX(0,Допущения!C5-Сценарии!C7*1000000*Допущения!C7)/Допущения!C7)*Допущения!C6)))+(Сценарии!C7*1000000-MAX(0,MAX(0,Допущения!C5-Сценарии!C7*1000000*Допущения!C7)-IF(MAX(0,Допущения!C5-Сценарии!C7*1000000*Допущения!C7)=0,Сценарии!C7*1000000*Допущения!C6,IF(MAX(0,Допущения!C5-Сценарии!C7*1000000*Допущения!C7)>=Сценарии!C7*1000000*Допущения!C7,Сценарии!C7*1000000*Допущения!C7,MAX(0,Допущения!C5-Сценарии!C7*1000000*Допущения!C7)+(Сценарии!C7*1000000-MAX(0,Допущения!C5-Сценарии!C7*1000000*Допущения!C7)/Допущения!C7)*Допущения!C6)))/Допущения!C7)*Допущения!C6))*(C5/Допущения!C5) -> 1561718.2 | D29: =Сценарии!D7*1000000*Допущения!C7*(C5/Допущения!C5)+IF(MAX(0,Допущения!C5-Сценарии!D7*1000000*Допущения!C7)=0,Сценарии!D7*1000000*Допущения!C6,IF(MAX(0,Допущения!C5-Сценарии!D7*1000000*Допущения!C7)>=Сценарии!D7*1000000*Допущения!C7,Сценарии!D7*1000000*Допущения!C7,MAX(0,Допущения!C5-Сценарии!D7*1000000*Допущения!C7)+(Сценарии!D7*1000000-MAX(0,Допущения!C5-Сценарии!D7*1000000*Допущения!C7)/Допущения!C7)*Допущения!C6))*(C5/Допущения!C5)+IF(MAX(0,MAX(0,Допущения!C5-Сценарии!D7*1000000*Допущения!C7)-IF(MAX(0,Допущения!C5-Сценарии!D7*1000000*Допущения!C7)=0,Сценарии!D7*1000000*Допущения!C6,IF(MAX(0,Допущения!C5-Сценарии!D7*1000000*Допущения!C7)>=Сценарии!D7*1000000*Допущения!C7,Сценарии!D7*1000000*Допущения!C7,MAX(0,Допущения!C5-Сценарии!D7*1000000*Допущения!C7)+(Сценарии!D7*1000000-MAX(0,Допущения!C5-Сценарии!D7*1000000*Допущения!C7)/Допущения!C7)*Допущения!C6)))=0,Сценарии!D7*1000000*Допущения!C6,IF(MAX(0,MAX(0,Допущения!C5-Сценарии!D7*1000000*Допущения!C7)-IF(MAX(0,Допущения!C5-Сценарии!D7*1000000*Допущения!C7)=0,Сценарии!D7*1000000*Допущения!C6,IF(MAX(0,Допущения!C5-Сценарии!D7*1000000*Допущения!C7)>=Сценарии!D7*1000000*Допущения!C7,Сценарии!D7*1000000*Допущения!C7,MAX(0,Допущения!C5-Сценарии!D7*1000000*Допущения!C7)+(Сценарии!D7*1000000-MAX(0,Допущения!C5-Сценарии!D7*1000000*Допущения!C7)/Допущения!C7)*Допущения!C6)))>=Сценарии!D7*1000000*Допущения!C7,Сценарии!D7*1000000*Допущения!C7,MAX(0,MAX(0,Допущения!C5-Сценарии!D7*1000000*Допущения!C7)-IF(MAX(0,Допущения!C5-Сценарии!D7*1000000*Допущения!C7)=0,Сценарии!D7*1000000*Допущения!C6,IF(MAX(0,Допущения!C5-Сценарии!D7*1000000*Допущения!C7)>=Сценарии!D7*1000000*Допущения!C7,Сценарии!D7*1000000*Допущения!C7,MAX(0,Допущения!C5-Сценарии!D7*1000000*Допущения!C7)+(Сценарии!D7*1000000-MAX(0,Допущения!C5-Сценарии!D7*1000000*Допущения!C7)/Допущения!C7)*Допущения!C6)))+(Сценарии!D7*1000000-MAX(0,MAX(0,Допущения!C5-Сценарии!D7*1000000*Допущения!C7)-IF(MAX(0,Допущения!C5-Сценарии!D7*1000000*Допущения!C7)=0,Сценарии!D7*1000000*Допущения!C6,IF(MAX(0,Допущения!C5-Сценарии!D7*1000000*Допущения!C7)>=Сценарии!D7*1000000*Допущения!C7,Сценарии!D7*1000000*Допущения!C7,MAX(0,Допущения!C5-Сценарии!D7*1000000*Допущения!C7)+(Сценарии!D7*1000000-MAX(0,Допущения!C5-Сценарии!D7*1000000*Допущения!C7)/Допущения!C7)*Допущения!C6)))/Допущения!C7)*Допущения!C6))*(C5/Допущения!C5) -> 1855272.7 | E29: =Сценарии!E7*1000000*Допущения!C7*(C5/Допущения!C5)+IF(MAX(0,Допущения!C5-Сценарии!E7*1000000*Допущения!C7)=0,Сценарии!E7*1000000*Допущения!C6,IF(MAX(0,Допущения!C5-Сценарии!E7*1000000*Допущения!C7)>=Сценарии!E7*1000000*Допущения!C7,Сценарии!E7*1000000*Допущения!C7,MAX(0,Допущения!C5-Сценарии!E7*1000000*Допущения!C7)+(Сценарии!E7*1000000-MAX(0,Допущения!C5-Сценарии!E7*1000000*Допущения!C7)/Допущения!C7)*Допущения!C6))*(C5/Допущения!C5)+IF(MAX(0,MAX(0,Допущения!C5-Сценарии!E7*1000000*Допущения!C7)-IF(MAX(0,Допущения!C5-Сценарии!E7*1000000*Допущения!C7)=0,Сценарии!E7*1000000*Допущения!C6,IF(MAX(0,Допущения!C5-Сценарии!E7*1000000*Допущения!C7)>=Сценарии!E7*1000000*Допущения!C7,Сценарии!E7*1000000*Допущения!C7,MAX(0,Допущения!C5-Сценарии!E7*1000000*Допущения!C7)+(Сценарии!E7*1000000-MAX(0,Допущения!C5-Сценарии!E7*1000000*Допущения!C7)/Допущения!C7)*Допущения!C6)))=0,Сценарии!E7*1000000*Допущения!C6,IF(MAX(0,MAX(0,Допущения!C5-Сценарии!E7*1000000*Допущения!C7)-IF(MAX(0,Допущения!C5-Сценарии!E7*1000000*Допущения!C7)=0,Сценарии!E7*1000000*Допущения!C6,IF(MAX(0,Допущения!C5-Сценарии!E7*1000000*Допущения!C7)>=Сценарии!E7*1000000*Допущения!C7,Сценарии!E7*1000000*Допущения!C7,MAX(0,Допущения!C5-Сценарии!E7*1000000*Допущения!C7)+(Сценарии!E7*1000000-MAX(0,Допущения!C5-Сценарии!E7*1000000*Допущения!C7)/Допущения!C7)*Допущения!C6)))>=Сценарии!E7*1000000*Допущения!C7,Сценарии!E7*1000000*Допущения!C7,MAX(0,MAX(0,Допущения!C5-Сценарии!E7*1000000*Допущения!C7)-IF(MAX(0,Допущения!C5-Сценарии!E7*1000000*Допущения!C7)=0,Сценарии!E7*1000000*Допущения!C6,IF(MAX(0,Допущения!C5-Сценарии!E7*1000000*Допущения!C7)>=Сценарии!E7*1000000*Допущения!C7,Сценарии!E7*1000000*Допущения!C7,MAX(0,Допущения!C5-Сценарии!E7*1000000*Допущения!C7)+(Сценарии!E7*1000000-MAX(0,Допущения!C5-Сценарии!E7*1000000*Допущения!C7)/Допущения!C7)*Допущения!C6)))+(Сценарии!E7*1000000-MAX(0,MAX(0,Допущения!C5-Сценарии!E7*1000000*Допущения!C7)-IF(MAX(0,Допущения!C5-Сценарии!E7*1000000*Допущения!C7)=0,Сценарии!E7*1000000*Допущения!C6,IF(MAX(0,Допущения!C5-Сценарии!E7*1000000*Допущения!C7)>=Сценарии!E7*1000000*Допущения!C7,Сценарии!E7*1000000*Допущения!C7,MAX(0,Допущения!C5-Сценарии!E7*1000000*Допущения!C7)+(Сценарии!E7*1000000-MAX(0,Допущения!C5-Сценарии!E7*1000000*Допущения!C7)/Допущения!C7)*Допущения!C6)))/Допущения!C7)*Допущения!C6))*(C5/Допущения!C5) -> 2148827.3
B31: СТОИМОСТЬ ВАШЕЙ ДОЛИ ПРИ ПРОДАЖЕ (оценка: прибыль × 3×)
B33: Годовая прибыль проекта (1 сезон) | C33: =Сценарии!C7 -> 52.72 | D33: =Сценарии!D7 -> 65.9 | E33: =Сценарии!E7 -> 79.08
B34: Оценка компании (прибыль × 3×) | C34: =Сценарии!C12 -> 158.16 | D34: =Сценарии!D12 -> 197.7 | E34: =Сценарии!E12 -> 237.24
B35: Стоимость доли всех инвесторов (49%) | C35: =Сценарии!C13 -> 77.4984 | D35: =Сценарии!D13 -> 96.873 | E35: =Сценарии!E13 -> 116.2476
B36: 📈 Стоимость ВАШИХ акций при продаже | C36: =Сценарии!C13*1000000*(C5/Допущения!C5) -> 1174218.2 | D36: =Сценарии!D13*1000000*(C5/Допущения!C5) -> 1467772.7 | E36: =Сценарии!E13*1000000*(C5/Допущения!C5) -> 1761327.3
B37: Прирост стоимости (сверх вложений) | C37: =Сценарии!C13*1000000*(C5/Допущения!C5)-C5 -> 174218.18 | D37: =Сценарии!D13*1000000*(C5/Допущения!C5)-C5 -> 467772.73 | E37: =Сценарии!E13*1000000*(C5/Допущения!C5)-C5 -> 761327.27
B39: ИТОГОВЫЙ РАСЧЁТ — СУММАРНЫЙ ДОХОД ЗА 3 ГОДА
B41: Дивиденды за 2027–2029 годы | C41: =Сценарии!C7*1000000*Допущения!C7*(C5/Допущения!C5)+IF(MAX(0,Допущения!C5-Сценарии!C7*1000000*Допущения!C7)=0,Сценарии!C7*1000000*Допущения!C6,IF(MAX(0,Допущения!C5-Сценарии!C7*1000000*Допущения!C7)>=Сценарии!C7*1000000*Допущения!C7,Сценарии!C7*1000000*Допущения!C7,MAX(0,Допущения!C5-Сценарии!C7*1000000*Допущения!C7)+(Сценарии!C7*1000000-MAX(0,Допущения!C5-Сценарии!C7*1000000*Допущения!C7)/Допущения!C7)*Допущения!C6))*(C5/Допущения!C5)+IF(MAX(0,MAX(0,Допущения!C5-Сценарии!C7*1000000*Допущения!C7)-IF(MAX(0,Допущения!C5-Сценарии!C7*1000000*Допущения!C7)=0,Сценарии!C7*1000000*Допущения!C6,IF(MAX(0,Допущения!C5-Сценарии!C7*1000000*Допущения!C7)>=Сценарии!C7*1000000*Допущения!C7,Сценарии!C7*1000000*Допущения!C7,MAX(0,Допущения!C5-Сценарии!C7*1000000*Допущения!C7)+(Сценарии!C7*1000000-MAX(0,Допущения!C5-Сценарии!C7*1000000*Допущения!C7)/Допущения!C7)*Допущения!C6)))=0,Сценарии!C7*1000000*Допущения!C6,IF(MAX(0,MAX(0,Допущения!C5-Сценарии!C7*1000000*Допущения!C7)-IF(MAX(0,Допущения!C5-Сценарии!C7*1000000*Допущения!C7)=0,Сценарии!C7*1000000*Допущения!C6,IF(MAX(0,Допущения!C5-Сценарии!C7*1000000*Допущения!C7)>=Сценарии!C7*1000000*Допущения!C7,Сценарии!C7*1000000*Допущения!C7,MAX(0,Допущения!C5-Сценарии!C7*1000000*Допущения!C7)+(Сценарии!C7*1000000-MAX(0,Допущения!C5-Сценарии!C7*1000000*Допущения!C7)/Допущения!C7)*Допущения!C6)))>=Сценарии!C7*1000000*Допущения!C7,Сценарии!C7*1000000*Допущения!C7,MAX(0,MAX(0,Допущения!C5-Сценарии!C7*1000000*Допущения!C7)-IF(MAX(0,Допущения!C5-Сценарии!C7*1000000*Допущения!C7)=0,Сценарии!C7*1000000*Допущения!C6,IF(MAX(0,Допущения!C5-Сценарии!C7*1000000*Допущения!C7)>=Сценарии!C7*1000000*Допущения!C7,Сценарии!C7*1000000*Допущения!C7,MAX(0,Допущения!C5-Сценарии!C7*1000000*Допущения!C7)+(Сценарии!C7*1000000-MAX(0,Допущения!C5-Сценарии!C7*1000000*Допущения!C7)/Допущения!C7)*Допущения!C6)))+(Сценарии!C7*1000000-MAX(0,MAX(0,Допущения!C5-Сценарии!C7*1000000*Допущения!C7)-IF(MAX(0,Допущения!C5-Сценарии!C7*1000000*Допущения!C7)=0,Сценарии!C7*1000000*Допущения!C6,IF(MAX(0,Допущения!C5-Сценарии!C7*1000000*Допущения!C7)>=Сценарии!C7*1000000*Допущения!C7,Сценарии!C7*1000000*Допущения!C7,MAX(0,Допущения!C5-Сценарии!C7*1000000*Допущения!C7)+(Сценарии!C7*1000000-MAX(0,Допущения!C5-Сценарии!C7*1000000*Допущения!C7)/Допущения!C7)*Допущения!C6)))/Допущения!C7)*Допущения!C6))*(C5/Допущения!C5) -> 1561718.2 | D41: =Сценарии!D7*1000000*Допущения!C7*(C5/Допущения!C5)+IF(MAX(0,Допущения!C5-Сценарии!D7*1000000*Допущения!C7)=0,Сценарии!D7*1000000*Допущения!C6,IF(MAX(0,Допущения!C5-Сценарии!D7*1000000*Допущения!C7)>=Сценарии!D7*1000000*Допущения!C7,Сценарии!D7*1000000*Допущения!C7,MAX(0,Допущения!C5-Сценарии!D7*1000000*Допущения!C7)+(Сценарии!D7*1000000-MAX(0,Допущения!C5-Сценарии!D7*1000000*Допущения!C7)/Допущения!C7)*Допущения!C6))*(C5/Допущения!C5)+IF(MAX(0,MAX(0,Допущения!C5-Сценарии!D7*1000000*Допущения!C7)-IF(MAX(0,Допущения!C5-Сценарии!D7*1000000*Допущения!C7)=0,Сценарии!D7*1000000*Допущения!C6,IF(MAX(0,Допущения!C5-Сценарии!D7*1000000*Допущения!C7)>=Сценарии!D7*1000000*Допущения!C7,Сценарии!D7*1000000*Допущения!C7,MAX(0,Допущения!C5-Сценарии!D7*1000000*Допущения!C7)+(Сценарии!D7*1000000-MAX(0,Допущения!C5-Сценарии!D7*1000000*Допущения!C7)/Допущения!C7)*Допущения!C6)))=0,Сценарии!D7*1000000*Допущения!C6,IF(MAX(0,MAX(0,Допущения!C5-Сценарии!D7*1000000*Допущения!C7)-IF(MAX(0,Допущения!C5-Сценарии!D7*1000000*Допущения!C7)=0,Сценарии!D7*1000000*Допущения!C6,IF(MAX(0,Допущения!C5-Сценарии!D7*1000000*Допущения!C7)>=Сценарии!D7*1000000*Допущения!C7,Сценарии!D7*1000000*Допущения!C7,MAX(0,Допущения!C5-Сценарии!D7*1000000*Допущения!C7)+(Сценарии!D7*1000000-MAX(0,Допущения!C5-Сценарии!D7*1000000*Допущения!C7)/Допущения!C7)*Допущения!C6)))>=Сценарии!D7*1000000*Допущения!C7,Сценарии!D7*1000000*Допущения!C7,MAX(0,MAX(0,Допущения!C5-Сценарии!D7*1000000*Допущения!C7)-IF(MAX(0,Допущения!C5-Сценарии!D7*1000000*Допущения!C7)=0,Сценарии!D7*1000000*Допущения!C6,IF(MAX(0,Допущения!C5-Сценарии!D7*1000000*Допущения!C7)>=Сценарии!D7*1000000*Допущения!C7,Сценарии!D7*1000000*Допущения!C7,MAX(0,Допущения!C5-Сценарии!D7*1000000*Допущения!C7)+(Сценарии!D7*1000000-MAX(0,Допущения!C5-Сценарии!D7*1000000*Допущения!C7)/Допущения!C7)*Допущения!C6)))+(Сценарии!D7*1000000-MAX(0,MAX(0,Допущения!C5-Сценарии!D7*1000000*Допущения!C7)-IF(MAX(0,Допущения!C5-Сценарии!D7*1000000*Допущения!C7)=0,Сценарии!D7*1000000*Допущения!C6,IF(MAX(0,Допущения!C5-Сценарии!D7*1000000*Допущения!C7)>=Сценарии!D7*1000000*Допущения!C7,Сценарии!D7*1000000*Допущения!C7,MAX(0,Допущения!C5-Сценарии!D7*1000000*Допущения!C7)+(Сценарии!D7*1000000-MAX(0,Допущения!C5-Сценарии!D7*1000000*Допущения!C7)/Допущения!C7)*Допущения!C6)))/Допущения!C7)*Допущения!C6))*(C5/Допущения!C5) -> 1855272.7 | E41: =Сценарии!E7*1000000*Допущения!C7*(C5/Допущения!C5)+IF(MAX(0,Допущения!C5-Сценарии!E7*1000000*Допущения!C7)=0,Сценарии!E7*1000000*Допущения!C6,IF(MAX(0,Допущения!C5-Сценарии!E7*1000000*Допущения!C7)>=Сценарии!E7*1000000*Допущения!C7,Сценарии!E7*1000000*Допущения!C7,MAX(0,Допущения!C5-Сценарии!E7*1000000*Допущения!C7)+(Сценарии!E7*1000000-MAX(0,Допущения!C5-Сценарии!E7*1000000*Допущения!C7)/Допущения!C7)*Допущения!C6))*(C5/Допущения!C5)+IF(MAX(0,MAX(0,Допущения!C5-Сценарии!E7*1000000*Допущения!C7)-IF(MAX(0,Допущения!C5-Сценарии!E7*1000000*Допущения!C7)=0,Сценарии!E7*1000000*Допущения!C6,IF(MAX(0,Допущения!C5-Сценарии!E7*1000000*Допущения!C7)>=Сценарии!E7*1000000*Допущения!C7,Сценарии!E7*1000000*Допущения!C7,MAX(0,Допущения!C5-Сценарии!E7*1000000*Допущения!C7)+(Сценарии!E7*1000000-MAX(0,Допущения!C5-Сценарии!E7*1000000*Допущения!C7)/Допущения!C7)*Допущения!C6)))=0,Сценарии!E7*1000000*Допущения!C6,IF(MAX(0,MAX(0,Допущения!C5-Сценарии!E7*1000000*Допущения!C7)-IF(MAX(0,Допущения!C5-Сценарии!E7*1000000*Допущения!C7)=0,Сценарии!E7*1000000*Допущения!C6,IF(MAX(0,Допущения!C5-Сценарии!E7*1000000*Допущения!C7)>=Сценарии!E7*1000000*Допущения!C7,Сценарии!E7*1000000*Допущения!C7,MAX(0,Допущения!C5-Сценарии!E7*1000000*Допущения!C7)+(Сценарии!E7*1000000-MAX(0,Допущения!C5-Сценарии!E7*1000000*Допущения!C7)/Допущения!C7)*Допущения!C6)))>=Сценарии!E7*1000000*Допущения!C7,Сценарии!E7*1000000*Допущения!C7,MAX(0,MAX(0,Допущения!C5-Сценарии!E7*1000000*Допущения!C7)-IF(MAX(0,Допущения!C5-Сценарии!E7*1000000*Допущения!C7)=0,Сценарии!E7*1000000*Допущения!C6,IF(MAX(0,Допущения!C5-Сценарии!E7*1000000*Допущения!C7)>=Сценарии!E7*1000000*Допущения!C7,Сценарии!E7*1000000*Допущения!C7,MAX(0,Допущения!C5-Сценарии!E7*1000000*Допущения!C7)+(Сценарии!E7*1000000-MAX(0,Допущения!C5-Сценарии!E7*1000000*Допущения!C7)/Допущения!C7)*Допущения!C6)))+(Сценарии!E7*1000000-MAX(0,MAX(0,Допущения!C5-Сценарии!E7*1000000*Допущения!C7)-IF(MAX(0,Допущения!C5-Сценарии!E7*1000000*Допущения!C7)=0,Сценарии!E7*1000000*Допущения!C6,IF(MAX(0,Допущения!C5-Сценарии!E7*1000000*Допущения!C7)>=Сценарии!E7*1000000*Допущения!C7,Сценарии!E7*1000000*Допущения!C7,MAX(0,Допущения!C5-Сценарии!E7*1000000*Допущения!C7)+(Сценарии!E7*1000000-MAX(0,Допущения!C5-Сценарии!E7*1000000*Допущения!C7)/Допущения!C7)*Допущения!C6)))/Допущения!C7)*Допущения!C6))*(C5/Допущения!C5) -> 2148827.3
B42: Стоимость ваших акций (продажа) | C42: =Сценарии!C13*1000000*(C5/Допущения!C5) -> 1174218.2 | D42: =Сценарии!D13*1000000*(C5/Допущения!C5) -> 1467772.7 | E42: =Сценарии!E13*1000000*(C5/Допущения!C5) -> 1761327.3
B43: 🏆 TOTAL RETURN — суммарный доход | C43: =(Сценарии!C7*1000000*Допущения!C7+IF(MAX(0,Допущения!C5-Сценарии!C7*1000000*Допущения!C7)=0,Сценарии!C7*1000000*Допущения!C6,IF(MAX(0,Допущения!C5-Сценарии!C7*1000000*Допущения!C7)>=Сценарии!C7*1000000*Допущения!C7,Сценарии!C7*1000000*Допущения!C7,MAX(0,Допущения!C5-Сценарии!C7*1000000*Допущения!C7)+(Сценарии!C7*1000000-MAX(0,Допущения!C5-Сценарии!C7*1000000*Допущения!C7)/Допущения!C7)*Допущения!C6))+IF(MAX(0,MAX(0,Допущения!C5-Сценарии!C7*1000000*Допущения!C7)-IF(MAX(0,Допущения!C5-Сценарии!C7*1000000*Допущения!C7)=0,Сценарии!C7*1000000*Допущения!C6,IF(MAX(0,Допущения!C5-Сценарии!C7*1000000*Допущения!C7)>=Сценарии!C7*1000000*Допущения!C7,Сценарии!C7*1000000*Допущения!C7,MAX(0,Допущения!C5-Сценарии!C7*1000000*Допущения!C7)+(Сценарии!C7*1000000-MAX(0,Допущения!C5-Сценарии!C7*1000000*Допущения!C7)/Допущения!C7)*Допущения!C6)))=0,Сценарии!C7*1000000*Допущения!C6,IF(MAX(0,MAX(0,Допущения!C5-Сценарии!C7*1000000*Допущения!C7)-IF(MAX(0,Допущения!C5-Сценарии!C7*1000000*Допущения!C7)=0,Сценарии!C7*1000000*Допущения!C6,IF(MAX(0,Допущения!C5-Сценарии!C7*1000000*Допущения!C7)>=Сценарии!C7*1000000*Допущения!C7,Сценарии!C7*1000000*Допущения!C7,MAX(0,Допущения!C5-Сценарии!C7*1000000*Допущения!C7)+(Сценарии!C7*1000000-MAX(0,Допущения!C5-Сценарии!C7*1000000*Допущения!C7)/Допущения!C7)*Допущения!C6)))>=Сценарии!C7*1000000*Допущения!C7,Сценарии!C7*1000000*Допущения!C7,MAX(0,MAX(0,Допущения!C5-Сценарии!C7*1000000*Допущения!C7)-IF(MAX(0,Допущения!C5-Сценарии!C7*1000000*Допущения!C7)=0,Сценарии!C7*1000000*Допущения!C6,IF(MAX(0,Допущения!C5-Сценарии!C7*1000000*Допущения!C7)>=Сценарии!C7*1000000*Допущения!C7,Сценарии!C7*1000000*Допущения!C7,MAX(0,Допущения!C5-Сценарии!C7*1000000*Допущения!C7)+(Сценарии!C7*1000000-MAX(0,Допущения!C5-Сценарии!C7*1000000*Допущения!C7)/Допущения!C7)*Допущения!C6)))+(Сценарии!C7*1000000-MAX(0,MAX(0,Допущения!C5-Сценарии!C7*1000000*Допущения!C7)-IF(MAX(0,Допущения!C5-Сценарии!C7*1000000*Допущения!C7)=0,Сценарии!C7*1000000*Допущения!C6,IF(MAX(0,Допущения!C5-Сценарии!C7*1000000*Допущения!C7)>=Сценарии!C7*1000000*Допущения!C7,Сценарии!C7*1000000*Допущения!C7,MAX(0,Допущения!C5-Сценарии!C7*1000000*Допущения!C7)+(Сценарии!C7*1000000-MAX(0,Допущения!C5-Сценарии!C7*1000000*Допущения!C7)/Допущения!C7)*Допущения!C6)))/Допущения!C7)*Допущения!C6)))*(C5/Допущения!C5)+Сценарии!C13*1000000*(C5/Допущения!C5) -> 2735936.4 | D43: =(Сценарии!D7*1000000*Допущения!C7+IF(MAX(0,Допущения!C5-Сценарии!D7*1000000*Допущения!C7)=0,Сценарии!D7*1000000*Допущения!C6,IF(MAX(0,Допущения!C5-Сценарии!D7*1000000*Допущения!C7)>=Сценарии!D7*1000000*Допущения!C7,Сценарии!D7*1000000*Допущения!C7,MAX(0,Допущения!C5-Сценарии!D7*1000000*Допущения!C7)+(Сценарии!D7*1000000-MAX(0,Допущения!C5-Сценарии!D7*1000000*Допущения!C7)/Допущения!C7)*Допущения!C6))+IF(MAX(0,MAX(0,Допущения!C5-Сценарии!D7*1000000*Допущения!C7)-IF(MAX(0,Допущения!C5-Сценарии!D7*1000000*Допущения!C7)=0,Сценарии!D7*1000000*Допущения!C6,IF(MAX(0,Допущения!C5-Сценарии!D7*1000000*Допущения!C7)>=Сценарии!D7*1000000*Допущения!C7,Сценарии!D7*1000000*Допущения!C7,MAX(0,Допущения!C5-Сценарии!D7*1000000*Допущения!C7)+(Сценарии!D7*1000000-MAX(0,Допущения!C5-Сценарии!D7*1000000*Допущения!C7)/Допущения!C7)*Допущения!C6)))=0,Сценарии!D7*1000000*Допущения!C6,IF(MAX(0,MAX(0,Допущения!C5-Сценарии!D7*1000000*Допущения!C7)-IF(MAX(0,Допущения!C5-Сценарии!D7*1000000*Допущения!C7)=0,Сценарии!D7*1000000*Допущения!C6,IF(MAX(0,Допущения!C5-Сценарии!D7*1000000*Допущения!C7)>=Сценарии!D7*1000000*Допущения!C7,Сценарии!D7*1000000*Допущения!C7,MAX(0,Допущения!C5-Сценарии!D7*1000000*Допущения!C7)+(Сценарии!D7*1000000-MAX(0,Допущения!C5-Сценарии!D7*1000000*Допущения!C7)/Допущения!C7)*Допущения!C6)))>=Сценарии!D7*1000000*Допущения!C7,Сценарии!D7*1000000*Допущения!C7,MAX(0,MAX(0,Допущения!C5-Сценарии!D7*1000000*Допущения!C7)-IF(MAX(0,Допущения!C5-Сценарии!D7*1000000*Допущения!C7)=0,Сценарии!D7*1000000*Допущения!C6,IF(MAX(0,Допущения!C5-Сценарии!D7*1000000*Допущения!C7)>=Сценарии!D7*1000000*Допущения!C7,Сценарии!D7*1000000*Допущения!C7,MAX(0,Допущения!C5-Сценарии!D7*1000000*Допущения!C7)+(Сценарии!D7*1000000-MAX(0,Допущения!C5-Сценарии!D7*1000000*Допущения!C7)/Допущения!C7)*Допущения!C6)))+(Сценарии!D7*1000000-MAX(0,MAX(0,Допущения!C5-Сценарии!D7*1000000*Допущения!C7)-IF(MAX(0,Допущения!C5-Сценарии!D7*1000000*Допущения!C7)=0,Сценарии!D7*1000000*Допущения!C6,IF(MAX(0,Допущения!C5-Сценарии!D7*1000000*Допущения!C7)>=Сценарии!D7*1000000*Допущения!C7,Сценарии!D7*1000000*Допущения!C7,MAX(0,Допущения!C5-Сценарии!D7*1000000*Допущения!C7)+(Сценарии!D7*1000000-MAX(0,Допущения!C5-Сценарии!D7*1000000*Допущения!C7)/Допущения!C7)*Допущения!C6)))/Допущения!C7)*Допущения!C6)))*(C5/Допущения!C5)+Сценарии!D13*1000000*(C5/Допущения!C5) -> 3323045.5 | E43: =(Сценарии!E7*1000000*Допущения!C7+IF(MAX(0,Допущения!C5-Сценарии!E7*1000000*Допущения!C7)=0,Сценарии!E7*1000000*Допущения!C6,IF(MAX(0,Допущения!C5-Сценарии!E7*1000000*Допущения!C7)>=Сценарии!E7*1000000*Допущения!C7,Сценарии!E7*1000000*Допущения!C7,MAX(0,Допущения!C5-Сценарии!E7*1000000*Допущения!C7)+(Сценарии!E7*1000000-MAX(0,Допущения!C5-Сценарии!E7*1000000*Допущения!C7)/Допущения!C7)*Допущения!C6))+IF(MAX(0,MAX(0,Допущения!C5-Сценарии!E7*1000000*Допущения!C7)-IF(MAX(0,Допущения!C5-Сценарии!E7*1000000*Допущения!C7)=0,Сценарии!E7*1000000*Допущения!C6,IF(MAX(0,Допущения!C5-Сценарии!E7*1000000*Допущения!C7)>=Сценарии!E7*1000000*Допущения!C7,Сценарии!E7*1000000*Допущения!C7,MAX(0,Допущения!C5-Сценарии!E7*1000000*Допущения!C7)+(Сценарии!E7*1000000-MAX(0,Допущения!C5-Сценарии!E7*1000000*Допущения!C7)/Допущения!C7)*Допущения!C6)))=0,Сценарии!E7*1000000*Допущения!C6,IF(MAX(0,MAX(0,Допущения!C5-Сценарии!E7*1000000*Допущения!C7)-IF(MAX(0,Допущения!C5-Сценарии!E7*1000000*Допущения!C7)=0,Сценарии!E7*1000000*Допущения!C6,IF(MAX(0,Допущения!C5-Сценарии!E7*1000000*Допущения!C7)>=Сценарии!E7*1000000*Допущения!C7,Сценарии!E7*1000000*Допущения!C7,MAX(0,Допущения!C5-Сценарии!E7*1000000*Допущения!C7)+(Сценарии!E7*1000000-MAX(0,Допущения!C5-Сценарии!E7*1000000*Допущения!C7)/Допущения!C7)*Допущения!C6)))>=Сценарии!E7*1000000*Допущения!C7,Сценарии!E7*1000000*Допущения!C7,MAX(0,MAX(0,Допущения!C5-Сценарии!E7*1000000*Допущения!C7)-IF(MAX(0,Допущения!C5-Сценарии!E7*1000000*Допущения!C7)=0,Сценарии!E7*1000000*Допущения!C6,IF(MAX(0,Допущения!C5-Сценарии!E7*1000000*Допущения!C7)>=Сценарии!E7*1000000*Допущения!C7,Сценарии!E7*1000000*Допущения!C7,MAX(0,Допущения!C5-Сценарии!E7*1000000*Допущения!C7)+(Сценарии!E7*1000000-MAX(0,Допущения!C5-Сценарии!E7*1000000*Допущения!C7)/Допущения!C7)*Допущения!C6)))+(Сценарии!E7*1000000-MAX(0,MAX(0,Допущения!C5-Сценарии!E7*1000000*Допущения!C7)-IF(MAX(0,Допущения!C5-Сценарии!E7*1000000*Допущения!C7)=0,Сценарии!E7*1000000*Допущения!C6,IF(MAX(0,Допущения!C5-Сценарии!E7*1000000*Допущения!C7)>=Сценарии!E7*1000000*Допущения!C7,Сценарии!E7*1000000*Допущения!C7,MAX(0,Допущения!C5-Сценарии!E7*1000000*Допущения!C7)+(Сценарии!E7*1000000-MAX(0,Допущения!C5-Сценарии!E7*1000000*Допущения!C7)/Допущения!C7)*Допущения!C6)))/Допущения!C7)*Допущения!C6)))*(C5/Допущения!C5)+Сценарии!E13*1000000*(C5/Допущения!C5) -> 3910154.5
B44: Кратность к вложению (×) | C44: =C43/C5 -> 2.7359364 | D44: =D43/C5 -> 3.3230455 | E44: =E43/C5 -> 3.9101545
B45: Вложено | C45: =C5 -> 1000000 | D45: =C5 -> 1000000 | E45: =C5 -> 1000000
B46: Чистый доход (total return − вложения) | C46: =(Сценарии!C7*1000000*Допущения!C7+IF(MAX(0,Допущения!C5-Сценарии!C7*1000000*Допущения!C7)=0,Сценарии!C7*1000000*Допущения!C6,IF(MAX(0,Допущения!C5-Сценарии!C7*1000000*Допущения!C7)>=Сценарии!C7*1000000*Допущения!C7,Сценарии!C7*1000000*Допущения!C7,MAX(0,Допущения!C5-Сценарии!C7*1000000*Допущения!C7)+(Сценарии!C7*1000000-MAX(0,Допущения!C5-Сценарии!C7*1000000*Допущения!C7)/Допущения!C7)*Допущения!C6))+IF(MAX(0,MAX(0,Допущения!C5-Сценарии!C7*1000000*Допущения!C7)-IF(MAX(0,Допущения!C5-Сценарии!C7*1000000*Допущения!C7)=0,Сценарии!C7*1000000*Допущения!C6,IF(MAX(0,Допущения!C5-Сценарии!C7*1000000*Допущения!C7)>=Сценарии!C7*1000000*Допущения!C7,Сценарии!C7*1000000*Допущения!C7,MAX(0,Допущения!C5-Сценарии!C7*1000000*Допущения!C7)+(Сценарии!C7*1000000-MAX(0,Допущения!C5-Сценарии!C7*1000000*Допущения!C7)/Допущения!C7)*Допущения!C6)))=0,Сценарии!C7*1000000*Допущения!C6,IF(MAX(0,MAX(0,Допущения!C5-Сценарии!C7*1000000*Допущения!C7)-IF(MAX(0,Допущения!C5-Сценарии!C7*1000000*Допущения!C7)=0,Сценарии!C7*1000000*Допущения!C6,IF(MAX(0,Допущения!C5-Сценарии!C7*1000000*Допущения!C7)>=Сценарии!C7*1000000*Допущения!C7,Сценарии!C7*1000000*Допущения!C7,MAX(0,Допущения!C5-Сценарии!C7*1000000*Допущения!C7)+(Сценарии!C7*1000000-MAX(0,Допущения!C5-Сценарии!C7*1000000*Допущения!C7)/Допущения!C7)*Допущения!C6)))>=Сценарии!C7*1000000*Допущения!C7,Сценарии!C7*1000000*Допущения!C7,MAX(0,MAX(0,Допущения!C5-Сценарии!C7*1000000*Допущения!C7)-IF(MAX(0,Допущения!C5-Сценарии!C7*1000000*Допущения!C7)=0,Сценарии!C7*1000000*Допущения!C6,IF(MAX(0,Допущения!C5-Сценарии!C7*1000000*Допущения!C7)>=Сценарии!C7*1000000*Допущения!C7,Сценарии!C7*1000000*Допущения!C7,MAX(0,Допущения!C5-Сценарии!C7*1000000*Допущения!C7)+(Сценарии!C7*1000000-MAX(0,Допущения!C5-Сценарии!C7*1000000*Допущения!C7)/Допущения!C7)*Допущения!C6)))+(Сценарии!C7*1000000-MAX(0,MAX(0,Допущения!C5-Сценарии!C7*1000000*Допущения!C7)-IF(MAX(0,Допущения!C5-Сценарии!C7*1000000*Допущения!C7)=0,Сценарии!C7*1000000*Допущения!C6,IF(MAX(0,Допущения!C5-Сценарии!C7*1000000*Допущения!C7)>=Сценарии!C7*1000000*Допущения!C7,Сценарии!C7*1000000*Допущения!C7,MAX(0,Допущения!C5-Сценарии!C7*1000000*Допущения!C7)+(Сценарии!C7*1000000-MAX(0,Допущения!C5-Сценарии!C7*1000000*Допущения!C7)/Допущения!C7)*Допущения!C6)))/Допущения!C7)*Допущения!C6)))*(C5/Допущения!C5)+Сценарии!C13*1000000*(C5/Допущения!C5)-C5 -> 1735936.4 | D46: =(Сценарии!D7*1000000*Допущения!C7+IF(MAX(0,Допущения!C5-Сценарии!D7*1000000*Допущения!C7)=0,Сценарии!D7*1000000*Допущения!C6,IF(MAX(0,Допущения!C5-Сценарии!D7*1000000*Допущения!C7)>=Сценарии!D7*1000000*Допущения!C7,Сценарии!D7*1000000*Допущения!C7,MAX(0,Допущения!C5-Сценарии!D7*1000000*Допущения!C7)+(Сценарии!D7*1000000-MAX(0,Допущения!C5-Сценарии!D7*1000000*Допущения!C7)/Допущения!C7)*Допущения!C6))+IF(MAX(0,MAX(0,Допущения!C5-Сценарии!D7*1000000*Допущения!C7)-IF(MAX(0,Допущения!C5-Сценарии!D7*1000000*Допущения!C7)=0,Сценарии!D7*1000000*Допущения!C6,IF(MAX(0,Допущения!C5-Сценарии!D7*1000000*Допущения!C7)>=Сценарии!D7*1000000*Допущения!C7,Сценарии!D7*1000000*Допущения!C7,MAX(0,Допущения!C5-Сценарии!D7*1000000*Допущения!C7)+(Сценарии!D7*1000000-MAX(0,Допущения!C5-Сценарии!D7*1000000*Допущения!C7)/Допущения!C7)*Допущения!C6)))=0,Сценарии!D7*1000000*Допущения!C6,IF(MAX(0,MAX(0,Допущения!C5-Сценарии!D7*1000000*Допущения!C7)-IF(MAX(0,Допущения!C5-Сценарии!D7*1000000*Допущения!C7)=0,Сценарии!D7*1000000*Допущения!C6,IF(MAX(0,Допущения!C5-Сценарии!D7*1000000*Допущения!C7)>=Сценарии!D7*1000000*Допущения!C7,Сценарии!D7*1000000*Допущения!C7,MAX(0,Допущения!C5-Сценарии!D7*1000000*Допущения!C7)+(Сценарии!D7*1000000-MAX(0,Допущения!C5-Сценарии!D7*1000000*Допущения!C7)/Допущения!C7)*Допущения!C6)))>=Сценарии!D7*1000000*Допущения!C7,Сценарии!D7*1000000*Допущения!C7,MAX(0,MAX(0,Допущения!C5-Сценарии!D7*1000000*Допущения!C7)-IF(MAX(0,Допущения!C5-Сценарии!D7*1000000*Допущения!C7)=0,Сценарии!D7*1000000*Допущения!C6,IF(MAX(0,Допущения!C5-Сценарии!D7*1000000*Допущения!C7)>=Сценарии!D7*1000000*Допущения!C7,Сценарии!D7*1000000*Допущения!C7,MAX(0,Допущения!C5-Сценарии!D7*1000000*Допущения!C7)+(Сценарии!D7*1000000-MAX(0,Допущения!C5-Сценарии!D7*1000000*Допущения!C7)/Допущения!C7)*Допущения!C6)))+(Сценарии!D7*1000000-MAX(0,MAX(0,Допущения!C5-Сценарии!D7*1000000*Допущения!C7)-IF(MAX(0,Допущения!C5-Сценарии!D7*1000000*Допущения!C7)=0,Сценарии!D7*1000000*Допущения!C6,IF(MAX(0,Допущения!C5-Сценарии!D7*1000000*Допущения!C7)>=Сценарии!D7*1000000*Допущения!C7,Сценарии!D7*1000000*Допущения!C7,MAX(0,Допущения!C5-Сценарии!D7*1000000*Допущения!C7)+(Сценарии!D7*1000000-MAX(0,Допущения!C5-Сценарии!D7*1000000*Допущения!C7)/Допущения!C7)*Допущения!C6)))/Допущения!C7)*Допущения!C6)))*(C5/Допущения!C5)+Сценарии!D13*1000000*(C5/Допущения!C5)-C5 -> 2323045.5 | E46: =(Сценарии!E7*1000000*Допущения!C7+IF(MAX(0,Допущения!C5-Сценарии!E7*1000000*Допущения!C7)=0,Сценарии!E7*1000000*Допущения!C6,IF(MAX(0,Допущения!C5-Сценарии!E7*1000000*Допущения!C7)>=Сценарии!E7*1000000*Допущения!C7,Сценарии!E7*1000000*Допущения!C7,MAX(0,Допущения!C5-Сценарии!E7*1000000*Допущения!C7)+(Сценарии!E7*1000000-MAX(0,Допущения!C5-Сценарии!E7*1000000*Допущения!C7)/Допущения!C7)*Допущения!C6))+IF(MAX(0,MAX(0,Допущения!C5-Сценарии!E7*1000000*Допущения!C7)-IF(MAX(0,Допущения!C5-Сценарии!E7*1000000*Допущения!C7)=0,Сценарии!E7*1000000*Допущения!C6,IF(MAX(0,Допущения!C5-Сценарии!E7*1000000*Допущения!C7)>=Сценарии!E7*1000000*Допущения!C7,Сценарии!E7*1000000*Допущения!C7,MAX(0,Допущения!C5-Сценарии!E7*1000000*Допущения!C7)+(Сценарии!E7*1000000-MAX(0,Допущения!C5-Сценарии!E7*1000000*Допущения!C7)/Допущения!C7)*Допущения!C6)))=0,Сценарии!E7*1000000*Допущения!C6,IF(MAX(0,MAX(0,Допущения!C5-Сценарии!E7*1000000*Допущения!C7)-IF(MAX(0,Допущения!C5-Сценарии!E7*1000000*Допущения!C7)=0,Сценарии!E7*1000000*Допущения!C6,IF(MAX(0,Допущения!C5-Сценарии!E7*1000000*Допущения!C7)>=Сценарии!E7*1000000*Допущения!C7,Сценарии!E7*1000000*Допущения!C7,MAX(0,Допущения!C5-Сценарии!E7*1000000*Допущения!C7)+(Сценарии!E7*1000000-MAX(0,Допущения!C5-Сценарии!E7*1000000*Допущения!C7)/Допущения!C7)*Допущения!C6)))>=Сценарии!E7*1000000*Допущения!C7,Сценарии!E7*1000000*Допущения!C7,MAX(0,MAX(0,Допущения!C5-Сценарии!E7*1000000*Допущения!C7)-IF(MAX(0,Допущения!C5-Сценарии!E7*1000000*Допущения!C7)=0,Сценарии!E7*1000000*Допущения!C6,IF(MAX(0,Допущения!C5-Сценарии!E7*1000000*Допущения!C7)>=Сценарии!E7*1000000*Допущения!C7,Сценарии!E7*1000000*Допущения!C7,MAX(0,Допущения!C5-Сценарии!E7*1000000*Допущения!C7)+(Сценарии!E7*1000000-MAX(0,Допущения!C5-Сценарии!E7*1000000*Допущения!C7)/Допущения!C7)*Допущения!C6)))+(Сценарии!E7*1000000-MAX(0,MAX(0,Допущения!C5-Сценарии!E7*1000000*Допущения!C7)-IF(MAX(0,Допущения!C5-Сценарии!E7*1000000*Допущения!C7)=0,Сценарии!E7*1000000*Допущения!C6,IF(MAX(0,Допущения!C5-Сценарии!E7*1000000*Допущения!C7)>=Сценарии!E7*1000000*Допущения!C7,Сценарии!E7*1000000*Допущения!C7,MAX(0,Допущения!C5-Сценарии!E7*1000000*Допущения!C7)+(Сценарии!E7*1000000-MAX(0,Допущения!C5-Сценарии!E7*1000000*Допущения!C7)/Допущения!C7)*Допущения!C6)))/Допущения!C7)*Допущения!C6)))*(C5/Допущения!C5)+Сценарии!E13*1000000*(C5/Допущения!C5)-C5 -> 2910154.5
B48: ℹ️ Механика расчёта: до полного возврата 66 млн ₽ всем инвесторам направляется 80% прибыли проекта, пропорционально долям вкладов. После полного возврата — 49% прибыли (совокупная доля инвесторов). Стоимость доли при продаже = прибыль × мультипликатор 3× × доля 49% × ваша пропорция. Все цифры рассчитываются автоматически на основе суммы в ячейке C5.

Sheet Дашборд
B1: LUCE SILVA — ИНВЕСТИЦИОННАЯ ФИНАНСОВАЯ МОДЕЛЬ
B2: Премиальная стеклянная оранжерея для свадеб | Москва и МО | 2027+
B3: Сценарий переключается на листе «Допущения» → ячейка C12 (1=Мин / 2=Базовый / 3=Макс)
B5: ПАРАМЕТРЫ ИНВЕСТИЦИЙ | D5: АКТИВНЫЙ СЦЕНАРИЙ
B6: Объём раунда | C6: =Допущения!C5 -> 66000000 | D6: Сценарий (1/2/3) | E6: =Допущения!C12 -> 2
B7: Доля инвестора | C7: =Допущения!C6 -> 0.49 | D7: Свадеб в сезон | E7: =Допущения!C13 -> 100
B8: Дивиденды до окупаемости | C8: =Допущения!C7 -> 0.8 | D8: Прибыль за сезон (млн ₽) | E8: =IF(Допущения!C12=1,Сценарии!C7,IF(Допущения!C12=2,Сценарии!D7,Сценарии!E7)) -> 65.9
B9: Мультипликатор оценки | C9: =Допущения!C9 -> 3 | D9: Инвестору (70%), млн ₽ | E9: =IF(Допущения!C12=1,Сценарии!C8,IF(Допущения!C12=2,Сценарии!D8,Сценарии!E8)) -> 52.72
B11: ЮНИТ-ЭКОНОМИКА ОДНОЙ СВАДЬБЫ | D11: CAPEX (66 МЛН ₽)
B12: Средний чек | C12: =Допущения!C21 -> 949000 | D12: Аренда земли | E12: =CAPEX!C4 -> 5000000
B13: Аренда площадки | C13: =Допущения!C22 -> 270000 | D13: Конструкция | E13: =CAPEX!C5 -> 22000000
B14: Кейтеринг | C14: =Допущения!C23 -> 604000 | D14: Инженерия | E14: =CAPEX!C6 -> 12000000
B15: Техника | C15: =Допущения!C24 -> 75000 | D15: Кухня | E15: =CAPEX!C7 -> 10000000
B16: COGS | C16: =Допущения!C25 -> 290000 | D16: Благоустройство | E16: =CAPEX!C8 -> 8000000
B17: Прибыль/свадьбу | C17: =Допущения!C26 -> 659000 | D17: Домик / хозблок | E17: =CAPEX!C9 -> 6000000
B18: Маржинальность | C18: =Допущения!C27 -> 0.69441517 | D18: Маркетинг и запуск | E18: =CAPEX!C10 -> 3000000
D19: ИТОГО CAPEX | E19: =CAPEX!C11 -> 66000000
B21: СРАВНЕНИЕ СЦЕНАРИЕВ
B22: Показатель | C22: МИН (75) | D22: БАЗОВЫЙ (100) | E22: МАКС (150)
B23: Прибыль сезон (млн) | C23: =Сценарии!C7 -> 52.72 | D23: =Сценарии!D7 -> 65.9 | E23: =Сценарии!E7 -> 79.08
B24: Инвестору 70% (млн) | C24: =Сценарии!C8 -> 42.176 | D24: =Сценарии!D8 -> 52.72 | E24: =Сценарии!E8 -> 63.264
B25: Доходность годовых | C25: =Сценарии!C9 -> 0.6390303 | D25: =Сценарии!D9 -> 0.79878788 | E25: =Сценарии!E9 -> 0.95854545
B26: Окупаемость (сезонов) | C26: =Сценарии!C10 -> 1.564871 | D26: =Сценарии!D10 -> 1.2518968 | E26: =Сценарии!E10 -> 1.0432473
B27: Оценка компании (млн) | C27: =Сценарии!C12 -> 158.16 | D27: =Сценарии!D12 -> 197.7 | E27: =Сценарии!E12 -> 237.24
B28: Доля 49% (млн) | C28: =Сценарии!C13 -> 77.4984 | D28: =Сценарии!D13 -> 96.873 | E28: =Сценарии!E13 -> 116.2476
B29: Total Return 3 сезона (млн) | C29: =Оценка!C15 -> 187.6832 | D29: =Оценка!D15 -> 234.604 | E29: =Оценка!E15 -> 281.5248
B30: Кратность к вложениям | C30: =Оценка!C16 -> 2.8436848 | D30: =Оценка!D16 -> 3.5546061 | E30: =Оценка!E16 -> 4.2655273
B32: УСЛОВНЫЕ ОБОЗНАЧЕНИЯ
B33: ■■■■■ | C33: Синий + голубой фон = исходные данные
B34: ■■■■■ | C34: Жёлтый фон = допущение аналитика (можно корректировать)
B35: ■■■■■ | C35: Зелёный текст = ссылка на другой лист
B36: ■■■■■ | C36: Чёрный текст = расчётная формула

Sheet Допущения
B1: ДОПУЩЕНИЯ И ВВОДНЫЕ — LUCE SILVA
B2: 🔵 Синий | 🟡 Жёлтый фон (допущение аналитика) | Ячейка C12 — переключатель сценария
C3: Значение | E3: Комментарий
B4: 1. ИНВЕСТИЦИОННЫЕ ПАРАМЕТРЫ
B5: Объём инвестиционного раунда | C5: 66000000
B6: Доля инвестора в компании | C6: 0.49
B7: Дивиденды до окупаемости (% прибыли) | C7: 0.8 | E7: Повышенная ставка до возврата
B8: Минимальный чек входа | C8: 1000000
B9: Мультипликатор оценки (x прибыли) | C9: 3
B11: 2. ВЫБОР СЦЕНАРИЯ
B12: Активный сценарий (1=Мин / 2=Базовый / 3=Макс) | C12: 2 | E12: ← МЕНЯЙТЕ ЗДЕСЬ для переключения сценария
B13: Свадеб в сезон (активный сценарий) | C13: =CHOOSE(C12,C16,C17,C18) -> 100 | E13: Автоматически по выбранному сценарию
B15: 3. СЦЕНАРИИ (свадеб в сезон,
B16: Минимальный сценарий | C16: 80 | E16: → прибыль ~52,7 млн ₽
B17: Базовый сценарий | C17: 100 | E17: → прибыль 50 млн ₽
B18: Максимальный сценарий | C18: 120 | E18: → прибыль ~79,1 млн ₽
B20: 4. ЮНИТ-ЭКОНОМИКА ОДНОЙ СВАДЬБЫ
B21: Средний чек (аренда + кейтеринг + техника) | C21: =C22+C23+C24 -> 949000 | E21: Автоматически: C22+C23+C24
B22: — Аренда площадки | C22: 270000 | E22: Средняя, июнь–сентябрь
B23: — Кейтеринг + сервисный сбор 15% | C23: 604000 | E23: 70 гостей: 525К + 15% сервисный сбор
B24: — Техника (свет, звук) | C24: 75000
B25: Переменная себестоимость (COGS) | C25: 290000 | E25: Продукты, персонал, логистика, налоги
B26: Прибыль с одной свадьбы | C26: =C21-C25 -> 659000 | E26: Выручка − COGS
B27: Маржинальность | C27: =C26/C21 -> 0.69441517 | E27: Прибыль / Выручка
B29: 5. СЕЗОННОСТЬ — ДОЛЯ СВАДЕБ ПО МЕСЯЦАМ
B30: Сезон май–октябрь. Помесячное распределение — допущение аналитика.
B31: Январь | C31: 0 | E31: Вне сезона
B32: Февраль | C32: 0 | E32: Вне сезона
B33: Март | C33: 0 | E33: Вне сезона
B34: Апрель | C34: 0 | E34: Вне сезона
B35: Май | C35: 0.15 | E35: [ASSUMPTION] типичный профиль свадебного сезона
B36: Июнь | C36: 0.2 | E36: [ASSUMPTION] типичный профиль свадебного сезона
B37: Июль | C37: 0.15 | E37: [ASSUMPTION] типичный профиль свадебного сезона
B38: Август | C38: 0.15 | E38: [ASSUMPTION] типичный профиль свадебного сезона
B39: Сентябрь | C39: 0.25 | E39: [ASSUMPTION] типичный профиль свадебного сезона
B40: Октябрь | C40: 0.1 | E40: [ASSUMPTION] типичный профиль свадебного сезона
B41: Ноябрь | C41: 0 | E41: Вне сезона
B42: Декабрь | C42: 0 | E42: Вне сезона
B43: ИТОГО (должно = 100%) | C43: =SUM(C31:C42) -> 1 | E43: Контроль: если ≠ 100%, пересмотрите распределение
B45: 6. ОПЕРАЦИОННЫЕ ДОПУЩЕНИЯ АНАЛИТИКА [НЕ
...

Sheet CAPEX
B1: CAPEX — ИНВЕСТИЦИОННЫЙ БЮДЖЕТ
B3: СТАТЬЯ CAPEX | C3: СУММА, ₽ | D3: ДОЛЯ | E3: КОММЕНТАРИЙ
B4: Аренда земли (10 лет, 1 га) | C4: 5000000 | D4: =C4/C11 -> 0.075757576 | E4: Предоплата за 10-летний договор
B5: Конструкция (стеклянная оранжерея) | C5: 22000000 | D5: =C5/C11 -> 0.33333333 | E5: Каркас, стекло, фундамент, кровля
B6: Инженерные системы | C6: 12000000 | D6: =C6/C11 -> 0.18181818 | E6: Электрика, тепло, вентиляция, водоснабжение
B7: Кухонное оборудование | C7: 10000000 | D7: =C7/C11 -> 0.15151515 | E7: Профессиональная кухня — собственный кейтеринг
B8: Благоустройство территории | C8: 8000000 | D8: =C8/C11 -> 0.12121212 | E8: Настил, освещение, ландшафт, парковка
B9: Домик / хозблок | C9: 6000000 | D9: =C9/C11 -> 0.090909091 | E9: Гостевой домик: 15 тыс ₽/сутки — доп. доход
B10: Маркетинг и запуск | C10: 3000000 | D10: =C10/C11 -> 0.045454545 | E10: Бренд, съёмки, SMM, открытие
B11: ИТОГО CAPEX | C11: =SUM(C4:C10) -> 66000000 | D11: 1
B13: ПРОВЕРКА: сумма должна = 66 000 000 ₽
B14: Итого CAPEX | C14: =C11 -> 66000000
B15: Целевой раунд | C15: =Допущения!C5 -> 66000000
B16: Разница (должна быть 0) | C16: =C11-Допущения!C5 -> 0
B18: РАСПРЕДЕЛЕНИЕ ПО СТАТЬЯМ
B19: Строительство + инженерия | C19: =C5+C6 -> 34000000
B20: Кухня + оборудование | C20: =C7 -> 10000000
B21: Благоустройство + домик | C21: =C8+C9 -> 14000000
B22: Земля + маркетинг | C22: =C4+C10 -> 8000000

Sheet Юнит-экономика
B1: ЮНИТ-ЭКОНОМИКА — ОДНА СВАДЬБА
B3: ВЫРУЧКА С ОДНОЙ СВАДЬБЫ (Источник: презентация)
B4: СТАТЬЯ | C4: СУММА | D4: % ВЫРУЧКИ | E4: ИСТОЧНИК
B5: Аренда площадки | C5: =Допущения!C22 -> 270000 | D5: =C5/Допущения!C21 -> 0.28451001
B6: Кейтеринг (собственная кухня) | C6: =Допущения!C23 -> 604000 | D6: =C6/Допущения!C21 -> 0.63645943
B7: Техника (свет, звук) | C7: =Допущения!C24 -> 75000 | D7: =C7/Допущения!C21 -> 0.079030558
B8: ИТОГО ВЫРУЧКА | C8: =Допущения!C21 -> 949000 | D8: =C8/C8 -> 1
B10: ПЕРЕМЕННЫЕ РАСХОДЫ (COGS) НА ОДНУ СВАДЬБУ
B11: СТАТЬЯ | C11: СУММА | D11: % ВЫРУЧКИ | E11: ПРИМЕЧАНИЕ
B12: Продукты и напитки | C12: 90000 | D12: =C12/Допущения!C21 -> 0.09483667 | E12: [ASSUMPTION] ~22% от выручки
B13: Персонал мероприятия | C13: 55000 | D13: =C13/Допущения!C21 -> 0.057955743 | E13: [ASSUMPTION] повара, официанты
B14: Логистика и клининг | C14: 30000 | D14: =C14/Допущения!C21 -> 0.031612223 | E14: [ASSUMPTION] доставка, уборка
B15: Охрана и коммунальные (event) | C15: 20000 | D15: =C15/Допущения!C21 -> 0.021074816 | E15: [ASSUMPTION] переменная часть
B16: Налоги и прочее | C16: 30000 | D16: =C16/Допущения!C21 -> 0.031612223 | E16: [ASSUMPTION] расчётная
B17: Итого по статьям (расчёт) | C17: =SUM(C12:C16) -> 225000 | D17: =C17/Допущения!C21 -> 0.23709168
B18: ИТОГО COGS | C18: =Допущения!C25 -> 290000 | D18: =C18/Допущения!C21 -> 0.30558483
B19: Разница (доп. COGS к распределению) | C19: =Допущения!C25-SUM(C12:C16) -> 65000
B21: P&L ОДНОЙ СВАДЬБЫ
B22: ПОКАЗАТЕЛЬ | C22: СУММА | D22: МАРЖА | E22: ИСТОЧНИК
B23: Выручка (средний чек) | C23: =Допущения!C21 -> 949000 | D23: =C23/C23 -> 1
B24: Переменная себестоимость | C24: =Допущения!C25 -> 290000 | D24: =C24/C23 -> 0.30558483
B25: ОПЕРАЦИОННАЯ ПРИБЫЛЬ | C25: =Допущения!C26 -> 659000 | D25: =C25/C23 -> 0.69441517 | E25: Выручка − COGS
B27: КОНТРОЛЬНЫЕ ЗНАЧЕНИЯ
B28: ПОКАЗАТЕЛЬ | C28: ПЛАН (презент.) | D28: МОДЕЛЬ | E28: СТАТУС
B29: Выручка | C29: 949000 | D29: =Допущения!C21 -> 949000 | E29: =IF(C29=D29,"✓ СОВПАДАЕТ","⚠ ПРОВЕРИТЬ") -> ✓ СОВПАДАЕТ
B30: COGS | C30: 290000 | D30: =Допущения!C25 -> 290000 | E30: =IF(C30=D30,"✓ СОВПАДАЕТ","⚠ ПРОВЕРИТЬ") -> ✓ СОВПАДАЕТ
B31: Прибыль | C31: 659000 | D31: =Допущения!C26 -> 659000 | E31: =IF(C31=D31,"✓ СОВПАДАЕТ","⚠ ПРОВЕРИТЬ") -> ✓ СОВПАДАЕТ

Sheet P&L 36 мес
B1: P&L — ПОМЕСЯЧНАЯ ФИНАНСОВАЯ МОДЕЛЬ (36 МЕСЯЦЕВ)
B2: Год / Месяц | C2: 2027 | D2: 2027 | E2: 2027 | F2: 2027 | G2: 2027 | H2: 2027 | I2: 2027 | J2: 2027 | K2: 2028 | L2: 2028 | M2: 2028 | N2: 2028 | O2: 2028 | P2: 2028 | Q2: 2028 | R2: 2028 | S2: 2028 | T2: 2028 | U2: 2028 | V2: 2028 | W2: 2029 | X2: 2029 | Y2: 2029 | Z2: 2029 | AA2: 2029 | AB2: 2029 | AC2: 2029 | AD2: 2029 | AE2: 2029 | AF2: 2029 | AG2: 2029 | AH2: 2029 | AI2: 2030 | AJ2: 2030 | AK2: 2030 | AL2: 2030 | AM2: Год 1 2027 | AN2: Год 2 2028 | AO2: Год 3 2029
B3: Показатель | C3: Май | D3: Июн | E3: Июл | F3: Авг | G3: Сен | H3: Окт | I3: Ноя | J3: Дек | K3: Янв | L3: Фев | M3: Мар | N3: Апр | O3: Май | P3: Июн | Q3: Июл | R3: Авг | S3: Сен | T3: Окт | U3: Ноя | V3: Дек | W3: Янв | X3: Фев | Y3: Мар | Z3: Апр | AA3: Май | AB3: Июн | AC3: Июл | AD3: Авг | AE3: Сен | AF3: Окт | AG3: Ноя | AH3: Дек | AI3: Янв | AJ3: Фев | AK3: Мар | AL3: Апр
B4: ВЫРУЧКА
B5: Количество свадеб | C5: =ROUND(Допущения!C13*Допущения!C35*Допущения!C47,0) -> 12 | D5: =ROUND(Допущения!C13*Допущения!C36*Допущения!C47,0) -> 16 | E5: =ROUND(Допущения!C13*Допущения!C37*Допущения!C47,0) -> 12 | F5: =ROUND(Допущения!C13*Допущения!C38*Допущения!C47,0) -> 12 | G5: =ROUND(Допущения!C13*Допущения!C39*Допущения!C47,0) -> 20 | H5: =ROUND(Допущения!C13*Допущения!C40*Допущения!C47,0) -> 8 | I5: 0 | J5: 0 | K5: 0 | L5: 0 | M5: 0 | N5: 0 | O5: =ROUND(Допущения!C13*Допущения!C35*Допущения!C48,0) -> 14 | P5: =ROUND(Допущения!C13*Допущения!C36*Допущения!C48,0) -> 18 | Q5: =ROUND(Допущения!C13*Допущения!C37*Допущения!C48,0) -> 14 | R5: =ROUND(Допущения!C13*Допущения!C38*Допущения!C48,0) -> 14 | S5: =ROUND(Допущения!C13*Допущения!C39*Допущения!C48,0) -> 23 | T5: =ROUND(Допущения!C13*Допущения!C40*Допущения!C48,0) -> 9 | U5: 0 | V5: 0 | W5: 0 | X5: 0 | Y5: 0 | Z5: 0 | AA5: =ROUND(Допущения!C13*Допущения!C35*Допущения!C49,0) -> 15 | AB5: =ROUND(Допущения!C13*Допущения!C36*Допущения!C49,0) -> 20 | AC5: =ROUND(Допущения!C13*Допущения!C37*Допущения!C49,0) -> 15 | AD5: =ROUND(Допущения!C13*Допущения!C38*Допущения!C49,0) -> 15 | AE5: =ROUND(Допущения!C13*Допущения!C39*Допущения!C49,0) -> 25 | AF5: =ROUND(Допущения!C13*Допущения!C40*Допущения!C49,0) -> 10 | AG5: 0 | AH5: 0 | AI5: 0 | AJ5: 0 | AK5: 0 | AL5: 0 | AM5: =SUM(C5:N5) -> 80 | AN5: =SUM(O5:Z5) -> 92 | AO5: =SUM(AA5:AL5) -> 100
B6: Выручка (₽) | C6: =C5*Допущения!C21*(1+Допущения!C50)^1 -> 12299040 | D6: =D5*Допущения!C21*(1+Допущения!C50)^1 -> 16398720 | E6: =E5*Допущения!C21*(1+Допущения!C50)^1 -> 12299040 | F6: =F5*Допущения!C21*(1+Допущения!C50)^1 -> 12299040 | G6: =G5*Допущения!C21*(1+Допущения!C50)^1 -> 20498400 | H6: =H5*Допущения!C21*(1+Допущения!C50)^1 -> 8199360 | I6: 0 | J6: 0 | K6: 0 | L6: 0 | M6: 0 | N6: 0 | O6: =O5*Допущения!C21*(1+Допущения!C50)^2 -> 15496790 | P6: =P5*Допущения!C21*(1+Допущения!C50)^2 -> 19924445 | Q6: =Q5*Допущения!C21*(1+Допущения!C50)^2 -> 15496790 | R6: =R5*Допущения!C21*(1+Допущения!C50)^2 -> 15496790 | S6: =S5*Допущения!C21*(1+Допущения!C50)^2 -> 25459013 | T6: =T5*Допущения!C21*(1+Допущения!C50)^2 -> 9962222.4 | U6: 0 | V6: 0 | W6: 0 | X6: 0 | Y6: 0 | Z6: 0 | AA6: =AA5*Допущения!C21*(1+Допущения!C50)^3 -> 17932000 | AB6: =AB5*Допущения!C21*(1+Допущения!C50)^3 -> 23909334 | AC6: =AC5*Допущения!C21*(1+Допущения!C50)^3 -> 17932000 | AD6: =AD5*Допущения!C21*(1+Допущения!C50)^3 -> 17932000 | AE6: =AE5*Допущения!C21*(1+Допущения!C50)^3 -> 29886667 | AF6: =AF5*Допущения!C21*(1+Допущения!C50)^3 -> 11954667 | AG6: 0 | AH6: 0 | AI6: 0 | AJ6: 0 | AK6: 0 | AL6: 0 | AM6: =SUM(C6:N6) -> 81993600 | AN6: =SUM(O6:Z6) -> 1.0183605e+08 | AO6: =SUM(AA6:AL6) -> 1.1954667e+08
